Workbook

Sheet import CapNhatTrungTuyen
A1: STT | B1: CCCD | C1: Mã ĐKXT | D1: Ngày sinh | E1: Giới tính | F1: Dân tộc | G1: Email SV | H1: MSSV | I1: Mật khẩu Online | J1: Email UEH | K1: Mật khẩu Email | L1: Tổng điểm | M1: ĐTC0 PT1 | N1: ĐTC0 PT2 | O1: Loại CCQT UID | P1: Số điểm CCQT | Q1: Ngày thi CCQT | R1: Ngày thi CCQT Mới | S1: ĐTB Lớp 10 | T1: ĐTB Lớp 11 | U1: ĐTB Lớp 12
A2: 1 | B2: 086308009238 | R2: 68.59 | T2: 67.76 | V2: 0
A3: 2 | B3: 086308006995 | R3: 64.7 | T3: 64.7 | V3: 0
A4: 3 | B4: 086208000490 | R4: 79.01 | T4: 76.68 | V4: 0
A5: 4 | B5: 083308010347 | R5: 67.99 | T5: 66.32 | V5: 0
A6: 5 | B6: 083308001521 | R6: 63.13 | T6: 61.46 | V6: 0
A7: 6 | B7: 082208015752 | R7: 67.71 | T7: 66.04
A8: 7 | B8: 079208042443 | R8: 88.94 | T8: 88.94 | V8: 7
A9: 8 | B9: 072308010254 | R9: 64.47 | T9: 63.64 | V9: 0
A10: 9 | B10: 066308006122 | R10: 77.51 | T10: 68.34 | V10: 0
A11: 10 | B11: 044208010722 | R11: 84.64 | T11: 83.54 | V11: 6.5
A12: 11 | B12: 040208024160 | R12: 73.95 | T12: 72.28 | V12: 0
A13: 12 | B13: 038208002727 | R13: 68.39 | T13: 67.56 | V13: 0
A14: 13 | B14: 008308006425 | C14: KSVBS2617443 | D14: 08016541 | J14: 08/01/2008 | K14: Nữ | L14: Kinh | M14: nhiv91608@gmail.com | R14: 80.56 | T14: 78.4 | V14: 0 | Y14: 8.46 | Z14: 8.5 | AA14: 8.72
A15: 14 | B15: 025308012169 | C15: KSVBS2629385 | D15: 25037325 | J15: 08/12/2008 | K15: Nữ | L15: Kinh | M15: khanhchi8812@gmail.com | N15: 31261570488 | O15: 27522792 | P15: chinguyen.31261570488@st.ueh.edu.vn | Q15: 27522792 | R15: 78.46 | T15: 77.72 | V15: 0 | Y15: 8.62 | Z15: 8.69 | AA15: 9.19
A16: 15 | B16: 033308007672 | C16: KSVBS2621873 | D16: 33005334 | J16: 20/04/2008 | K16: Nữ | L16: Kinh | M16: nhhang2@gmail.com | N16: 31261570513 | O16: 87102618 | P16: hangnguyen.31261570513@st.ueh.edu.vn | Q16: 87102618 | R16: 82.02 | T16: 81.4 | V16: 0 | Y16: 8.59 | Z16: 8.52 | AA16: 8.66
A17: 16 | B17: 034308005716 | C17: KSVBS2626874 | D17: 31021165 | J17: 25/10/2008 | K17: Nữ | L17: Kinh | M17: lphuong25102008@gmail.com | N17: 31261570490 | O17: 97019616 | P17: phuongnguyen.31261570490@st.ueh.edu.vn | Q17: 97019616 | R17: 76.22 | T17: 76.22 | V17: 0 | Y17: 8.68 | Z17: 8.11 | AA17: 8.93
A18: 17 | B18: 037308003748 | C18: KSVBS2603312 | D18: 37003959 | J18: 27/02/2008 | K18: Nữ | L18: Kinh | M18: phamlinh2722@gmail.com | N18: 31261570510 | O18: 84633605 | P18: linhpham.31261570510@st.ueh.edu.vn | Q18: 84633605 | R18: 67.49 | T18: 66.66 | V18: 0 | Y18: 7.06 | Z18: 7.54 | AA18: 7.7
A19: 18 | B19: 038307007810 | C19: KSVBS2613966 | D19: 75003150 | J19: 31/01/2007 | K19: Nữ | L19: Kinh | M19: nguyenngocbaoloan910@gmail.com | N19: 31261570511 | O19: 22019106 | P19: loannguyen.31261570511@st.ueh.edu.vn | Q19: 22019106 | R19: 75.77 | T19: 74.1 | V19: 0 | Y19: 8.18 | Z19: 8.72 | AA19: 8.74
A20: 19 | B20: 038308013704 | C20: KSVBS2620036 | D20: 79129945 | J20: 13/01/2008 | K20: Nữ | L20: Kinh | M20: hdo516516@gmail.com | N20: 31261570417 | O20: 68062150 | P20: huyendo.31261570417@st.ueh.edu.vn | Q20: 68062150 | R20: 62.87 | T20: 62.04 | V20: 0 | Y20: 8.03 | Z20: 8.01 | AA20: 8
A21: 20 | B21: 042307010416 | C21: KSVBS2618284 | D21: 42011184 | J21: 09/02/2007 | K21: Nữ | L21: Kinh | M21: nhit5753@gmail.com | N21: 31261570517 | O21: 40146008 | P21: nhitran.31261570517@st.ueh.edu.vn | Q21: 40146008 | R21: 64.67 | T21: 63 | V21: 0 | Y21: 6.69 | Z21: 7.73 | AA21: 8.11
A22: 21 | B22: 046206005798 | C22: KSVBS2646585 | D22: 46013275 | J22: 15/12/2006 | K22: Nam | L22: Kinh | M22: trannhattuyen3@gmail.com | R22: 66.15 | T22: 64.48 | V22: 0 | Y22: 7.43 | Z22: 7.81 | AA22: 8.06
A23: 22 | B23: 058307004501 | C23: KSVBS2631437 | D23: 79088789 | J23: 08/02/2007 | K23: Nữ | L23: Kinh | M23: votuyetle2007@gmail.com | N23: 31261570512 | O23: 54709450 | P23: levo.31261570512@st.ueh.edu.vn | Q23: 54709450 | R23: 65.47 | T23: 64.64 | V23: 0 | Y23: 7.48 | Z23: 7.71 | AA23: 7.58
A24: 23 | B24: 060308009190 | C24: KSVBS2643331 | D24: 68026368 | J24: 08/04/2008 | K24: Nữ | L24: Kinh | M24: ngocquyenbui.122@gmail.com | N24: 31261570524 | O24: 13239135 | P24: quyenbui.31261570524@st.ueh.edu.vn | Q24: 13239135 | R24: 80.81 | T24: 79.44 | V24: 0 | Y24: 8.42 | Z24: 8.83 | AA24: 8.92
A25: 24 | B25: 066208001338 | C25: KSVBS2603875 | D25: 66018672 | F25: Giải thưởng kỳ thi chọn học sinh giỏi cấp tỉnh/TP: | G25: Toán | H25: Nhì | I25: 2026 | J25: 21/12/2008 | K25: Nam | L25: Kinh | M25: giapdang122108@gmail.com | R25: 86.12 | T25: 85.64 | V25: 0 | Y25: 8.13 | Z25: 8.34 | AA25: 8.54
A26: 25 | B26: 066208003927 | C26: KSVBS2622794 | D26: 66012019 | J26: 07/12/2008 | K26: Nam | L26: Kinh | M26: giathinh712@gmail.com | N26: 31261570483 | O26: 93249165 | P26: thinhle.31261570483@st.ueh.edu.vn | Q26: 93249165 | R26: 80.34 | T26: 78.16 | V26: 0 | Y26: 8.28 | Z26: 8.88 | AA26: 8.53
A27: 26 | B27: 066308009933 | C27: KSVBS2610292 | D27: 66012061 | J27: 17/07/2008 | K27: Nữ | L27: Kinh | M27: tramlebao118@gmail.com | N27: 31261570521 | O27: 94437458 | P27: tramle.31261570521@st.ueh.edu.vn | Q27: 94437458 | R27: 77.63 | T27: 75.14 | V27: 0 | Y27: 8.3 | Z27: 8.17 | AA27: 8.54
A28: 27 | B28: 067308001789 | C28: KSVBS2641447 | D28: 68037533 | J28: 29/04/2008 | K28: Nữ | L28: Kinh | M28: vananhtrannguyen94@gmail.com | N28: 31261570518 | O28: 53102859 | P28: anhtran.31261570518@st.ueh.edu.vn | Q28: 53102859 | R28: 70.28 | T28: 67.78 | V28: 0 | Y28: 8.17 | Z28: 8.24 | AA28: 8.6
A29: 28 | B29: 068208002791 | C29: KSVBS2620084 | D29: 68010239 | J29: 23/12/2008 | K29: Nam | L29: Kinh | M29: ndmphuong2312@gmail.com | R29: 84.49 | T29: 83.38 | V29: 0 | Y29: 8.73 | Z29: 8.68 | AA29: 8.76
A30: 29 | B30: 068208007545 | C30: KSVBS2604269 | D30: 68009037 | F30: Giải thưởng kỳ thi chọn học sinh giỏi cấp tỉnh/TP: | G30: Toán | H30: Ba | I30: 2026 | J30: 12/02/2008 | K30: Nam | L30: Kinh | M30: anhvecaki692@gmail.com | R30: 90.48 | T30: 89.8 | V30: 0 | Y30: 8.96 | Z30: 8.86 | AA30: 8.51
A31: 30 | B31: 068208012324 | C31: KSVBS2608556 | D31: 68017988 | J31: 29/12/2008 | K31: Nam | L31: Kinh | M31: thienle.31261570410@st.ueh.edu.vn | R31: 67.17 | T31: 65.5 | V31: 0 | Y31: 7.24 | Z31: 7.02 | AA31: 7.41
A32: 31 | B32: 068308007047 | C32: KSVBS2648890 | D32: 68017743 | J32: 18/03/2008 | K32: Nữ | L32: Kinh | M32: tranthihaiha2008@gmail.com | N32: 31261570498 | O32: 46618392 | P32: hatran.31261570498@st.ueh.edu.vn | Q32: 46618392 | R32: 78.14 | T32: 76.58 | V32: 0 | Y32: 8.7 | Z32: 8.56 | AA32: 8.94
A33: 32 | B33: 075308018302 | C33: KSVBS2631425 | D33: 75021250 | J33: 28/01/2008 | K33: Nữ | L33: Kinh | M33: trngtranh830@gmail.com | N33: 31261570522 | O33: 36540494 | P33: anhtran.31261570522@st.ueh.edu.vn | Q33: 36540494 | R33: 63.37 | T33: 61.7 | V33: 0 | Y33: 7.07 | Z33: 7.29 | AA33: 7.13
A34: 33 | B34: 075308023084 | C34: KSVBS2610916 | D34: 75006902 | J34: 04/06/2008 | K34: Nữ | L34: Kinh | M34: nguyenhathuylinh8@gmail.com | N34: 31261570435 | O34: 51765438 | P34: linhnguyen.31261570435@st.ueh.edu.vn | Q34: 51765438 | R34: 73.75 | T34: 72.92 | V34: 0 | Y34: 7.72 | Z34: 7.79 | AA34: 7.69
A35: 34 | B35: 077208001964 | C35: KSVBS2622915 | D35: 79134235 | J35: 18/04/2008 | K35: Nam | L35: Kinh | M35: kimtrienbui@gmail.com | N35: 31261570471 | O35: 48630710 | P35: trienbui.31261570471@st.ueh.edu.vn | Q35: 48630710 | R35: 84.71 | T35: 83.62 | V35: 0 | Y35: 8.47 | Z35: 8.73 | AA35: 8.42
A36: 35 | B36: 077308001983 | C36: KSVBS2608241 | D36: 79133877 | J36: 12/07/2008 | K36: Nữ | L36: Kinh | M36: vuleequynhanh1278@gmail.com | N36: 31261570478 | O36: 81838721 | P36: anhvu.31261570478@st.ueh.edu.vn | Q36: 81838721 | R36: 71.09 | T36: 69.42 | V36: 0 | Y36: 7.57 | Z36: 7.88 | AA36: 8.21
A37: 36 | B37: 079308009276 | C37: KSVBS2640309 | D37: 79055743 | J37: 14/04/2008 | K37: Nữ | L37: Kinh | M37: nguyentranyennhi140408@gmail.com | N37: 31261570493 | O37: 58072374 | P37: nhinguyen.31261570493@st.ueh.edu.vn | Q37: 58072374 | R37: 81.98 | T37: 81.98 | U37: IELTS | V37: 6.5 | W37: 30/05/2026 | Y37: 9.39 | Z37: 9.29 | AA37: 9.42
A38: 37 | B38: 079308028343 | C38: KSVBS2615477 | D38: 79007817 | J38: 02/01/2008 | K38: Nữ | L38: Kinh | M38: thanhnam08071995@gmail.com | R38: 63.02 | T38: 63.02 | V38: 0 | Y38: 6.51 | Z38: 7.61 | AA38: 8.01
A39: 38 | B39: 079308035195 | C39: KSVBS2613129 | D39: 79086650 | J39: 02/04/2008 | K39: Nữ | L39: Kinh | M39: hoaithuongg242008@gmail.com | N39: 31261570418 | O39: 90737160 | P39: thuongle.31261570418@st.ueh.edu.vn | Q39: 90737160 | R39: 66.11 | T39: 65.28 | V39: 0 | Y39: 7.46 | Z39: 7.99 | AA39: 8.32
A40: 39 | B40: 079308045991 | C40: KSVBS2629470 | D40: 86015830 | J40: 02/11/2008 | K40: Nữ | L40: Kinh | M40: phwgahn0203@gmail.com | R40: 69.51 | T40: 68.68 | V40: 0 | Y40: 8.47 | Z40: 8.49 | AA40: 8.32
...

Sheet FILE CT (CHEP CCCD TU CHAY)
A1: STT | B1: CCCD | C1: Mã ĐKXT | D1: SBD | E1: Mã nơi sinh | F1: Tên giải HSG | G1: Tên môn HSG | H1: Tên hạng HSG | I1: Năm HSG | J1: Ngày sinh | K1: Giới tính | L1: Dân tộc | M1: Email SV | N1: Điện thoại | O1: MSSV | P1: Mật khẩu Online | Q1: Email UEH | R1: Mật khẩu Email | S1: Tổng điểm | T1: ĐTC0 PT1 | U1: ĐTC0 PT2 | V1: Loại CCQT UID | W1: Số điểm CCQT | X1: Ngày thi CCQT | Y1: Ngày thi CCQT Mới | Z1: ĐTB Lớp 10 | AA1: ĐTB Lớp 11 | AB1: ĐTB Lớp 12 | AE1: Cạp nhật cột này để lấy MSSV
A2: 1 | B2: 089308002325 | C2: =VLOOKUP(B2,'DANH SACH UEH'!$A$3:$FE$2228,2,0) -> KSVBS2624948 | D2: =IFERROR(VLOOKUP(B2,'DS NGHIEP VU BO'!$A$3:$BX$148,6,0),"") -> 91027079 | E2: =VLOOKUP(B2,'DS NGHIEP VU BO'!$A$3:$BX$148,45,0) -> An Giang | F2: =IF(G2<>"","Giải thưởng kỳ thi chọn học sinh giỏi cấp tỉnh/TP:","") | G2: =IFERROR(IF(VLOOKUP(B2,'DANH SACH UEH'!$A$3:$FE$2228,18,0)="Không có","",VLOOKUP(B2,'DANH SACH UEH'!$A$3:$FE$2228,18,0)),"") | H2: =IFERROR(IF(VLOOKUP(B2,'DANH SACH UEH'!$A$3:$FE$2228,20,0)="Không có","",VLOOKUP(B2,'DANH SACH UEH'!$A$3:$FE$2228,20,0)),"") | I2: =IFERROR(IF(VLOOKUP(B2,'DANH SACH UEH'!$A$3:$FE$2228,19,0)="Không có","",VLOOKUP(B2,'DANH SACH UEH'!$A$3:$FE$2228,19,0)),"") | J2: =VLOOKUP(B2,'DANH SACH UEH'!$A$3:$FE$2228,6,0) -> 29/06/2008 | K2: =IF(VLOOKUP(B2,'DANH SACH UEH'!$A$3:$FE$2228,5,0)="1","Nữ","Nam") -> Nữ | L2: =VLOOKUP(B2,'DANH SACH UEH'!$A$3:$FE$2228,14,0) -> Kinh | M2: =VLOOKUP(B2,'DANH SACH UEH'!$A$3:$FE$2228,7,0) -> duongthidieuthi110220@gmail.com | N2: =VLOOKUP(B2,'DANH SACH UEH'!$A$3:$FE$2228,8,0) -> 0901242703 | O2: =IFERROR(VLOOKUP(AE2,'DS TAO MAIL'!$D$3:$M$1120,5,0),"") -> 31261570441 | P2: =IFERROR(VLOOKUP(AE2,'DS TAO MAIL'!$D$3:$M$1120,8,0),"") -> 84285425 | Q2: =IFERROR(VLOOKUP(AE2,'DS TAO MAIL'!$D$3:$M$1120,7,0),"") -> thiduong.31261570441@st.ueh.edu.vn | R2: =IFERROR(VLOOKUP(AE2,'DS TAO MAIL'!$D$3:$M$1120,8,0),"") -> 84285425 | S2: 68.59 | U2: 67.76 | V2: =IFERROR(IF(VLOOKUP(B2,'DANH SACH UEH'!$A$3:$FE$2228,27,0)="Không có","",IF(VLOOKUP(B2,'DANH SACH UEH'!$A$3:$FE$2228,29,0)<"6","",(VLOOKUP(B2,'DANH SACH UEH'!$A$3:$FE$2228,27,0)))),"") | W2: =IFERROR(IF(VLOOKUP(B2,'DANH SACH UEH'!$A$3:$FE$2228,29,0)<"6","",VLOOKUP(B2,'DANH SACH UEH'!$A$3:$FE$2228,29,0)),"") | X2: =IFERROR(IF(V2="","",VLOOKUP(B2,'DANH SACH UEH'!$A$3:$FE$2228,28,0)&""),"") | Z2: =VLOOKUP(B2,'DANH SACH UEH'!$A$3:$FE$2228,44,0) -> 7.61 | AA2: =VLOOKUP(B2,'DANH SACH UEH'!$A$3:$FE$2228,45,0) -> 8.11 | AB2: =VLOOKUP(B2,'DANH SACH UEH'!$A$3:$FE$2228,46,0) -> 8.53 | AE2: =VLOOKUP(B2,'DANH SACH UEH'!$A$3:$I$2229,4,0) -> DƯƠNG THỊ DIỆU THI | AF2: =VLOOKUP(B2,'DANH SACH UEH'!$A$3:$I$2229,8,0) -> 0901242703
A3: 2 | B3: 089308000129 | C3: =VLOOKUP(B3,'DANH SACH UEH'!$A$3:$FE$2228,2,0) -> KSVBS2642636 | D3: =IFERROR(VLOOKUP(B3,'DS NGHIEP VU BO'!$A$3:$BX$148,6,0),"") -> 91021928 | E3: =VLOOKUP(B3,'DS NGHIEP VU BO'!$A$3:$BX$148,45,0) -> An Giang | F3: =IF(G3<>"","Giải thưởng kỳ thi chọn học sinh giỏi cấp tỉnh/TP:","") | G3: =IFERROR(IF(VLOOKUP(B3,'DANH SACH UEH'!$A$3:$FE$2228,18,0)="Không có","",VLOOKUP(B3,'DANH SACH UEH'!$A$3:$FE$2228,18,0)),"") | H3: =IFERROR(IF(VLOOKUP(B3,'DANH SACH UEH'!$A$3:$FE$2228,20,0)="Không có","",VLOOKUP(B3,'DANH SACH UEH'!$A$3:$FE$2228,20,0)),"") | I3: =IFERROR(IF(VLOOKUP(B3,'DANH SACH UEH'!$A$3:$FE$2228,19,0)="Không có","",VLOOKUP(B3,'DANH SACH UEH'!$A$3:$FE$2228,19,0)),"") | J3: =VLOOKUP(B3,'DANH SACH UEH'!$A$3:$FE$2228,6,0) -> 04/07/2008 | K3: =IF(VLOOKUP(B3,'DANH SACH UEH'!$A$3:$FE$2228,5,0)="1","Nữ","Nam") -> Nữ | L3: =VLOOKUP(B3,'DANH SACH UEH'!$A$3:$FE$2228,14,0) -> Kinh | M3: =VLOOKUP(B3,'DANH SACH UEH'!$A$3:$FE$2228,7,0) -> miphg0208@gmail.com | N3: =VLOOKUP(B3,'DANH SACH UEH'!$A$3:$FE$2228,8,0) -> 0948664820 | O3: =IFERROR(VLOOKUP(AE3,'DS TAO MAIL'!$D$3:$M$1120,5,0),"") -> 31261570519 | P3: =IFERROR(VLOOKUP(AE3,'DS TAO MAIL'!$D$3:$M$1120,8,0),"") -> 45355106 | Q3: =IFERROR(VLOOKUP(AE3,'DS TAO MAIL'!$D$3:$M$1120,7,0),"") -> phuongon.31261570519@st.ueh.edu.vn | R3: =IFERROR(VLOOKUP(AE3,'DS TAO MAIL'!$D$3:$M$1120,8,0),"") -> 45355106 | S3: 64.7 | U3: 64.7 | V3: =IFERROR(IF(VLOOKUP(B3,'DANH SACH UEH'!$A$3:$FE$2228,27,0)="Không có","",IF(VLOOKUP(B3,'DANH SACH UEH'!$A$3:$FE$2228,29,0)<"6","",(VLOOKUP(B3,'DANH SACH UEH'!$A$3:$FE$2228,27,0)))),"") -> IELTS | W3: =IFERROR(IF(VLOOKUP(B3,'DANH SACH UEH'!$A$3:$FE$2228,29,0)<"6","",VLOOKUP(B3,'DANH SACH UEH'!$A$3:$FE$2228,29,0)),"") -> 6 | X3: =IFERROR(IF(V3="","",VLOOKUP(B3,'DANH SACH UEH'!$A$3:$FE$2228,28,0)&""),"") -> 09/05/2026 | Z3: =VLOOKUP(B3,'DANH SACH UEH'!$A$3:$FE$2228,44,0) -> 8.00 | AA3: =VLOOKUP(B3,'DANH SACH UEH'!$A$3:$FE$2228,45,0) -> 8.12 | AB3: =VLOOKUP(B3,'DANH SACH UEH'!$A$3:$FE$2228,46,0) -> 8.20 | AE3: =VLOOKUP(B3,'DANH SACH UEH'!$A$3:$I$2229,4,0) -> ÔN MỸ PHƯƠNG | AF3: =VLOOKUP(B3,'DANH SACH UEH'!$A$3:$I$2229,8,0) -> 0948664820
A4: 3 | B4: 087308004435 | C4: =VLOOKUP(B4,'DANH SACH UEH'!$A$3:$FE$2228,2,0) -> KSVBS2649203 | D4: =IFERROR(VLOOKUP(B4,'DS NGHIEP VU BO'!$A$3:$BX$148,6,0),"") -> 82017938 | E4: =VLOOKUP(B4,'DS NGHIEP VU BO'!$A$3:$BX$148,45,0) -> Đồng Tháp | F4: =IF(G4<>"","Giải thưởng kỳ thi chọn học sinh giỏi cấp tỉnh/TP:","") | G4: =IFERROR(IF(VLOOKUP(B4,'DANH SACH UEH'!$A$3:$FE$2228,18,0)="Không có","",VLOOKUP(B4,'DANH SACH UEH'!$A$3:$FE$2228,18,0)),"") | H4: =IFERROR(IF(VLOOKUP(B4,'DANH SACH UEH'!$A$3:$FE$2228,20,0)="Không có","",VLOOKUP(B4,'DANH SACH UEH'!$A$3:$FE$2228,20,0)),"") | I4: =IFERROR(IF(VLOOKUP(B4,'DANH SACH UEH'!$A$3:$FE$2228,19,0)="Không có","",VLOOKUP(B4,'DANH SACH UEH'!$A$3:$FE$2228,19,0)),"") | J4: =VLOOKUP(B4,'DANH SACH UEH'!$A$3:$FE$2228,6,0) -> 03/01/2008 | K4: =IF(VLOOKUP(B4,'DANH SACH UEH'!$A$3:$FE$2228,5,0)="1","Nữ","Nam") -> Nữ | L4: =VLOOKUP(B4,'DANH SACH UEH'!$A$3:$FE$2228,14,0) -> Kinh | M4: =VLOOKUP(B4,'DANH SACH UEH'!$A$3:$FE$2228,7,0) -> manhyangho0301@gmail.com | N4: =VLOOKUP(B4,'DANH SACH UEH'!$A$3:$FE$2228,8,0) -> 0797280837 | O4: =IFERROR(VLOOKUP(AE4,'DS TAO MAIL'!$D$3:$M$1120,5,0),"") -> 31261570480 | P4: =IFERROR(VLOOKUP(AE4,'DS TAO MAIL'!$D$3:$M$1120,8,0),"") -> 60060213 | Q4: =IFERROR(VLOOKUP(AE4,'DS TAO MAIL'!$D$3:$M$1120,7,0),"") -> anhpham.31261570480@st.ueh.edu.vn | R4: =IFERROR(VLOOKUP(AE4,'DS TAO MAIL'!$D$3:$M$1120,8,0),"") -> 60060213 | S4: 79.01 | U4: 76.68 | V4: =IFERROR(IF(VLOOKUP(B4,'DANH SACH UEH'!$A$3:$FE$2228,27,0)="Không có","",IF(VLOOKUP(B4,'DANH SACH UEH'!$A$3:$FE$2228,29,0)<"6","",(VLOOKUP(B4,'DANH SACH UEH'!$A$3:$FE$2228,27,0)))),"") | W4: =IFERROR(IF(VLOOKUP(B4,'DANH SACH UEH'!$A$3:$FE$2228,29,0)<"6","",VLOOKUP(B4,'DANH SACH UEH'!$A$3:$FE$2228,29,0)),"") | X4: =IFERROR(IF(V4="","",VLOOKUP(B4,'DANH SACH UEH'!$A$3:$FE$2228,28,0)&""),"") | Z4: =VLOOKUP(B4,'DANH SACH UEH'!$A$3:$FE$2228,44,0) -> 8.57 | AA4: =VLOOKUP(B4,'DANH SACH UEH'!$A$3:$FE$2228,45,0) -> 8.79 | AB4: =VLOOKUP(B4,'DANH SACH UEH'!$A$3:$FE$2228,46,0) -> 8.81 | AE4: =VLOOKUP(B4,'DANH SACH UEH'!$A$3:$I$2229,4,0) -> PHẠM THỤY TRÂM ANH | AF4: =VLOOKUP(B4,'DANH SACH UEH'!$A$3:$I$2229,8,0) -> 0797280837
A5: 4 | B5: 091208003108 | C5: =VLOOKUP(B5,'DANH SACH UEH'!$A$3:$FE$2228,2,0) -> KSVBS2635356 | D5: =IFERROR(VLOOKUP(B5,'DS NGHIEP VU BO'!$A$3:$BX$148,6,0),"") -> 91020148 | E5: =VLOOKUP(B5,'DS NGHIEP VU BO'!$A$3:$BX$148,45,0) -> An Giang | F5: =IF(G5<>"","Giải thưởng kỳ thi chọn học sinh giỏi cấp tỉnh/TP:","") | G5: =IFERROR(IF(VLOOKUP(B5,'DANH SACH UEH'!$A$3:$FE$2228,18,0)="Không có","",VLOOKUP(B5,'DANH SACH UEH'!$A$3:$FE$2228,18,0)),"") | H5: =IFERROR(IF(VLOOKUP(B5,'DANH SACH UEH'!$A$3:$FE$2228,20,0)="Không có","",VLOOKUP(B5,'DANH SACH UEH'!$A$3:$FE$2228,20,0)),"") | I5: =IFERROR(IF(VLOOKUP(B5,'DANH SACH UEH'!$A$3:$FE$2228,19,0)="Không có","",VLOOKUP(B5,'DANH SACH UEH'!$A$3:$FE$2228,19,0)),"") | J5: =VLOOKUP(B5,'DANH SACH UEH'!$A$3:$FE$2228,6,0) -> 19/06/2008 | K5: =IF(VLOOKUP(B5,'DANH SACH UEH'!$A$3:$FE$2228,5,0)="1","Nữ","Nam") -> Nam | L5: =VLOOKUP(B5,'DANH SACH UEH'!$A$3:$FE$2228,14,0) -> Kinh | M5: =VLOOKUP(B5,'DANH SACH UEH'!$A$3:$FE$2228,7,0) -> huutrong07102022@gmail.com | N5: =VLOOKUP(B5,'DANH SACH UEH'!$A$3:$FE$2228,8,0) -> 0981728059 | O5: =IFERROR(VLOOKUP(AE5,'DS TAO MAIL'!$D$3:$M$1120,5,0),"") -> 31261570537 | P5: =IFERROR(VLOOKUP(AE5,'DS TAO MAIL'!$D$3:$M$1120,8,0),"") -> 63246509 | Q5: =IFERROR(VLOOKUP(AE5,'DS TAO MAIL'!$D$3:$M$1120,7,0),"") -> trongnguyen.31261570537@st.ueh.edu.vn | R5: =IFERROR(VLOOKUP(AE5,'DS TAO MAIL'!$D$3:$M$1120,8,0),"") -> 63246509 | S5: 67.99 | U5: 66.32 | V5: =IFERROR(IF(VLOOKUP(B5,'DANH SACH UEH'!$A$3:$FE$2228,27,0)="Không có","",IF(VLOOKUP(B5,'DANH SACH UEH'!$A$3:$FE$2228,29,0)<"6","",(VLOOKUP(B5,'DANH SACH UEH'!$A$3:$FE$2228,27,0)))),"") | W5: =IFERROR(IF(VLOOKUP(B5,'DANH SACH UEH'!$A$3:$FE$2228,29,0)<"6","",VLOOKUP(B5,'DANH SACH UEH'!$A$3:$FE$2228,29,0)),"") | X5: =IFERROR(IF(V5="","",VLOOKUP(B5,'DANH SACH UEH'!$A$3:$FE$2228,28,0)&""),"") | Z5: =VLOOKUP(B5,'DANH SACH UEH'!$A$3:$FE$2228,44,0) -> 7.10 | AA5: =VLOOKUP(B5,'DANH SACH UEH'!$A$3:$FE$2228,45,0) -> 7.36 | AB5: =VLOOKUP(B5,'DANH SACH UEH'!$A$3:$FE$2228,46,0) -> 8.39 | AE5: =VLOOKUP(B5,'DANH SACH UEH'!$A$3:$I$2229,4,0) -> NGUYỄN HỮU TRỌNG | AF5: =VLOOKUP(B5,'DANH SACH UEH'!$A$3:$I$2229,8,0) -> 0981728059
A6: 5 | B6: 089308002210 | C6: =VLOOKUP(B6,'DANH SACH UEH'!$A$3:$FE$2228,2,0) -> KSVBS2613894 | D6: =IFERROR(VLOOKUP(B6,'DS NGHIEP VU BO'!$A$3:$BX$148,6,0),"") -> 91016468 | E6: =VLOOKUP(B6,'DS NGHIEP VU BO'!$A$3:$BX$148,45,0) -> An Giang | F6: =IF(G6<>"","Giải thưởng kỳ thi chọn học sinh giỏi cấp tỉnh/TP:","") | G6: =IFERROR(IF(VLOOKUP(B6,'DANH SACH UEH'!$A$3:$FE$2228,18,0)="Không có","",VLOOKUP(B6,'DANH SACH UEH'!$A$3:$FE$2228,18,0)),"") | H6: =IFERROR(IF(VLOOKUP(B6,'DANH SACH UEH'!$A$3:$FE$2228,20,0)="Không có","",VLOOKUP(B6,'DANH SACH UEH'!$A$3:$FE$2228,20,0)),"") | I6: =IFERROR(IF(VLOOKUP(B6,'DANH SACH UEH'!$A$3:$FE$2228,19,0)="Không có","",VLOOKUP(B6,'DANH SACH UEH'!$A$3:$FE$2228,19,0)),"") | J6: =VLOOKUP(B6,'DANH SACH UEH'!$A$3:$FE$2228,6,0) -> 03/08/2008 | K6: =IF(VLOOKUP(B6,'DANH SACH UEH'!$A$3:$FE$2228,5,0)="1","Nữ","Nam") -> Nữ | L6: =VLOOKUP(B6,'DANH SACH UEH'!$A$3:$FE$2228,14,0) -> Kinh | M6: =VLOOKUP(B6,'DANH SACH UEH'!$A$3:$FE$2228,7,0) -> tn3188623@gmail.com | N6: =VLOOKUP(B6,'DANH SACH UEH'!$A$3:$FE$2228,8,0) -> 0926814889 | O6: =IFERROR(VLOOKUP(AF6,'DS TAO MAIL'!$A$3:$M$1120,8,0),"") | P6: =IFERROR(VLOOKUP(AF6,'DS TAO MAIL'!$A$3:$M$1120,11,0),"") | Q6: =IFERROR(VLOOKUP(AF6,'DS TAO MAIL'!$A$3:$M$1120,10,0),"") | R6: =IFERROR(VLOOKUP(AF6,'DS TAO MAIL'!$A$3:$M$1120,11,0),"") | S6: 63.13 | U6: 61.46 | V6: =IFERROR(IF(VLOOKUP(B6,'DANH SACH UEH'!$A$3:$FE$2228,27,0)="Không có","",IF(VLOOKUP(B6,'DANH SACH UEH'!$A$3:$FE$2228,29,0)<"6","",(VLOOKUP(B6,'DANH SACH UEH'!$A$3:$FE$2228,27,0)))),"") | W6: =IFERROR(IF(VLOOKUP(B6,'DANH SACH UEH'!$A$3:$FE$2228,29,0)<"6","",VLOOKUP(B6,'DANH SACH UEH'!$A$3:$FE$2228,29,0)),"") | X6: =IFERROR(IF(V6="","",VLOOKUP(B6,'DANH SACH UEH'!$A$3:$FE$2228,28,0)&""),"") | Z6: =VLOOKUP(B6,'DANH SACH UEH'!$A$3:$FE$2228,44,0) -> 7.96 | AA6: =VLOOKUP(B6,'DANH SACH UEH'!$A$3:$FE$2228,45,0) -> 8.14 | AB6: =VLOOKUP(B6,'DANH SACH UEH'!$A$3:$FE$2228,46,0) -> 8.44 | AE6: =VLOOKUP(B6,'DANH SACH UEH'!$A$3:$I$2229,4,0) -> NGUYỄN NGỌC MINH THƯ | AF6: =VLOOKUP(B6,'DANH SACH UEH'!$A$3:$I$2229,8,0) -> 0926814889
A7: 6 | B7: 083308007749 | C7: =VLOOKUP(B7,'DANH SACH UEH'!$A$3:$FE$2228,2,0) -> KSVBS2634521 | D7: =IFERROR(VLOOKUP(B7,'DS NGHIEP VU BO'!$A$3:$BX$148,6,0),"") -> 86004072 | E7: =VLOOKUP(B7,'DS NGHIEP VU BO'!$A$3:$BX$148,45,0) -> Vĩnh Long | F7: =IF(G7<>"","Giải thưởng kỳ thi chọn học sinh giỏi cấp tỉnh/TP:","") | G7: =IFERROR(IF(VLOOKUP(B7,'DANH SACH UEH'!$A$3:$FE$2228,18,0)="Không có","",VLOOKUP(B7,'DANH SACH UEH'!$A$3:$FE$2228,18,0)),"") | H7: =IFERROR(IF(VLOOKUP(B7,'DANH SACH UEH'!$A$3:$FE$2228,20,0)="Không có","",VLOOKUP(B7,'DANH SACH UEH'!$A$3:$FE$2228,20,0)),"") | I7: =IFERROR(IF(VLOOKUP(B7,'DANH SACH UEH'!$A$3:$FE$2228,19,0)="Không có","",VLOOKUP(B7,'DANH SACH UEH'!$A$3:$FE$2228,19,0)),"") | J7: =VLOOKUP(B7,'DANH SACH UEH'!$A$3:$FE$2228,6,0) -> 26/02/2008 | K7: =IF(VLOOKUP(B7,'DANH SACH UEH'!$A$3:$FE$2228,5,0)="1","Nữ","Nam") -> Nữ | L7: =VLOOKUP(B7,'DANH SACH UEH'!$A$3:$FE$2228,14,0) -> Kinh | M7: =VLOOKUP(B7,'DANH SACH UEH'!$A$3:$FE$2228,7,0) -> peklinh2602@gmail.com | N7: =VLOOKUP(B7,'DANH SACH UEH'!$A$3:$FE$2228,8,0) -> 0862590198 | O7: =IFERROR(VLOOKUP(AE7,'DS TAO MAIL'!$D$3:$M$1120,5,0),"") | P7: =IFERROR(VLOOKUP(AE7,'DS TAO MAIL'!$D$3:$M$1120,8,0),"") | Q7: =IFERROR(VLOOKUP(AE7,'DS TAO MAIL'!$D$3:$M$1120,7,0),"") | R7: =IFERROR(VLOOKUP(AE7,'DS TAO MAIL'!$D$3:$M$1120,8,0),"") | S7: 67.71 | U7: 66.04 | V7: =IFERROR(IF(VLOOKUP(B7,'DANH SACH UEH'!$A$3:$FE$2228,27,0)="Không có","",IF(VLOOKUP(B7,'DANH SACH UEH'!$A$3:$FE$2228,29,0)<"6","",(VLOOKUP(B7,'DANH SACH UEH'!$A$3:$FE$2228,27,0)))),"") | W7: =IFERROR(IF(VLOOKUP(B7,'DANH SACH UEH'!$A$3:$FE$2228,29,0)<"6","",VLOOKUP(B7,'DANH SACH UEH'!$A$3:$FE$2228,29,0)),"") | X7: =IFERROR(IF(V7="","",VLOOKUP(B7,'DANH SACH UEH'!$A$3:$FE$2228,28,0)&""),"") | Z7: =VLOOKUP(B7,'DANH SACH UEH'!$A$3:$FE$2228,44,0) -> 8.46 | AA7: =VLOOKUP(B7,'DANH SACH UEH'!$A$3:$FE$2228,45,0) -> 9.47 | AB7: =VLOOKUP(B7,'DANH SACH UEH'!$A$3:$FE$2228,46,0) -> 9.40 | AE7: =VLOOKUP(B7,'DANH SACH UEH'!$A$3:$I$2229,4,0) -> TÔ THỊ ÁNH LINH | AF7: =VLOOKUP(B7,'DANH SACH UEH'!$A$3:$I$2229,8,0) -> 0862590198
A8: 7 | B8: 086308009238 | C8: =VLOOKUP(B8,'DANH SACH UEH'!$A$3:$FE$2228,2,0) -> KSVBS2631718 | D8: =IFERROR(VLOOKUP(B8,'DS NGHIEP VU BO'!$A$3:$BX$148,6,0),"") -> 86015817 | E8: =VLOOKUP(B8,'DS NGHIEP VU BO'!$A$3:$BX$148,45,0) -> Vĩnh Long | F8: =IF(G8<>"","Giải thưởng kỳ thi chọn học sinh giỏi cấp tỉnh/TP:","") | G8: =IFERROR(IF(VLOOKUP(B8,'DANH SACH UEH'!$A$3:$FE$2228,18,0)="Không có","",VLOOKUP(B8,'DANH SACH UEH'!$A$3:$FE$2228,18,0)),"") | H8: =IFERROR(IF(VLOOKUP(B8,'DANH SACH UEH'!$A$3:$FE$2228,20,0)="Không có","",VLOOKUP(B8,'DANH SACH UEH'!$A$3:$FE$2228,20,0)),"") | I8: =IFERROR(IF(VLOOKUP(B8,'DANH SACH UEH'!$A$3:$FE$2228,19,0)="Không có","",VLOOKUP(B8,'DANH SACH UEH'!$A$3:$FE$2228,19,0)),"") | J8: =VLOOKUP(B8,'DANH SACH UEH'!$A$3:$FE$2228,6,0) -> 27/07/2008 | K8: =IF(VLOOKUP(B8,'DANH SACH UEH'!$A$3:$FE$2228,5,0)="1","Nữ","Nam") -> Nữ | L8: =VLOOKUP(B8,'DANH SACH UEH'!$A$3:$FE$2228,14,0) -> Kinh | M8: =VLOOKUP(B8,'DANH SACH UEH'!$A$3:$FE$2228,7,0) -> phucanle171913@gmail.com | N8: =VLOOKUP(B8,'DANH SACH UEH'!$A$3:$FE$2228,8,0) -> 0792398749 | O8: =IFERROR(VLOOKUP(AE8,'DS TAO MAIL'!$D$3:$M$1120,5,0),"") -> 31261570423 | P8: =IFERROR(VLOOKUP(AE8,'DS TAO MAIL'!$D$3:$M$1120,8,0),"") -> 60441217 | Q8: =IFERROR(VLOOKUP(AE8,'DS TAO MAIL'!$D$3:$M$1120,7,0),"") -> anle.31261570423@st.ueh.edu.vn | R8: =IFERROR(VLOOKUP(AE8,'DS TAO MAIL'!$D$3:$M$1120,8,0),"") -> 60441217 | S8: 88.94 | U8: 88.94 | V8: =IFERROR(IF(VLOOKUP(B8,'DANH SACH UEH'!$A$3:$FE$2228,27,0)="Không có","",IF(VLOOKUP(B8,'DANH SACH UEH'!$A$3:$FE$2228,29,0)<"6","",(VLOOKUP(B8,'DANH SACH UEH'!$A$3:$FE$2228,27,0)))),"") | W8: =IFERROR(IF(VLOOKUP(B8,'DANH SACH UEH'!$A$3:$FE$2228,29,0)<"6","",VLOOKUP(B8,'DANH SACH UEH'!$A$3:$FE$2228,29,0)),"") | X8: =IFERROR(IF(V8="","",VLOOKUP(B8,'DANH SACH UEH'!$A$3:$FE$2228,28,0)&""),"") | Z8: =VLOOKUP(B8,'DANH SACH UEH'!$A$3:$FE$2228,44,0) -> 8.47 | AA8: =VLOOKUP(B8,'DANH SACH UEH'!$A$3:$FE$2228,45,0) -> 8.60 | AB8: =VLOOKUP(B8,'DANH SACH UEH'!$A$3:$FE$2228,46,0) -> 8.64 | AE8: =VLOOKUP(B8,'DANH SACH UEH'!$A$3:$I$2229,4,0) -> LÊ PHÚC AN | AF8: =VLOOKUP(B8,'DANH SACH UEH'!$A$3:$I$2229,8,0) -> 0792398749
A9: 8 | B9: 086308006995 | C9: =VLOOKUP(B9,'DANH SACH UEH'!$A$3:$FE$2228,2,0) -> KSVBS2631682 | D9: =IFERROR(VLOOKUP(B9,'DS NGHIEP VU BO'!$A$3:$BX$148,6,0),"") -> 92014084 | E9: =VLOOKUP(B9,'DS NGHIEP VU BO'!$A$3:$BX$148,45,0) -> Vĩnh Long | F9: =IF(G9<>"","Giải thưởng kỳ thi chọn học sinh giỏi cấp tỉnh/TP:","") | G9: =IFERROR(IF(VLOOKUP(B9,'DANH SACH UEH'!$A$3:$FE$2228,18,0)="Không có","",VLOOKUP(B9,'DANH SACH UEH'!$A$3:$FE$2228,18,0)),"") | H9: =IFERROR(IF(VLOOKUP(B9,'DANH SACH UEH'!$A$3:$FE$2228,20,0)="Không có","",VLOOKUP(B9,'DANH SACH UEH'!$A$3:$FE$2228,20,0)),"") | I9: =IFERROR(IF(VLOOKUP(B9,'DANH SACH UEH'!$A$3:$FE$2228,19,0)="Không có","",VLOOKUP(B9,'DANH SACH UEH'!$A$3:$FE$2228,19,0)),"") | J9: =VLOOKUP(B9,'DANH SACH UEH'!$A$3:$FE$2228,6,0) -> 23/10/2008 | K9: =IF(VLOOKUP(B9,'DANH SACH UEH'!$A$3:$FE$2228,5,0)="1","Nữ","Nam") -> Nữ | L9: =VLOOKUP(B9,'DANH SACH UEH'!$A$3:$FE$2228,14,0) -> Kinh | M9: =VLOOKUP(B9,'DANH SACH UEH'!$A$3:$FE$2228,7,0) -> minhnguyetnguyenquoc@gmail.com | N9: =VLOOKUP(B9,'DANH SACH UEH'!$A$3:$FE$2228,8,0) -> 0846578578 | O9: =IFERROR(VLOOKUP(AE9,'DS TAO MAIL'!$D$3:$M$1120,5,0),"") -> 31261570502 | P9: =IFERROR(VLOOKUP(AE9,'DS TAO MAIL'!$D$3:$M$1120,8,0),"") -> 97481732 | Q9: =IFERROR(VLOOKUP(AE9,'DS TAO MAIL'!$D$3:$M$1120,7,0),"") -> nguyetnguyen.31261570502@st.ueh.edu.vn | R9: =IFERROR(VLOOKUP(AE9,'DS TAO MAIL'!$D$3:$M$1120,8,0),"") -> 97481732 | S9: 64.47 | U9: 63.64 | V9: =IFERROR(IF(VLOOKUP(B9,'DANH SACH UEH'!$A$3:$FE$2228,27,0)="Không có","",IF(VLOOKUP(B9,'DANH SACH UEH'!$A$3:$FE$2228,29,0)<"6","",(VLOOKUP(B9,'DANH SACH UEH'!$A$3:$FE$2228,27,0)))),"") | W9: =IFERROR(IF(VLOOKUP(B9,'DANH SACH UEH'!$A$3:$FE$2228,29,0)<"6","",VLOOKUP(B9,'DANH SACH UEH'!$A$3:$FE$2228,29,0)),"") | X9: =IFERROR(IF(V9="","",VLOOKUP(B9,'DANH SACH UEH'!$A$3:$FE$2228,28,0)&""),"") | Z9: =VLOOKUP(B9,'DANH SACH UEH'!$A$3:$FE$2228,44,0) -> 8.38 | AA9: =VLOOKUP(B9,'DANH SACH UEH'!$A$3:$FE$2228,45,0) -> 8.67 | AB9: =VLOOKUP(B9,'DANH SACH UEH'!$A$3:$FE$2228,46,0) -> 8.52 | AE9: =VLOOKUP(B9,'DANH SACH UEH'!$A$3:$I$2229,4,0) -> NGUYỄN QUỐC MINH NGUYỆT | AF9: =VLOOKUP(B9,'DANH SACH UEH'!$A$3:$I$2229,8,0) -> 0846578578
A10: 9 | B10: 086208000490 | C10: =VLOOKUP(B10,'DANH SACH UEH'!$A$3:$FE$2228,2,0) -> KSVBS2648154 | D10: =IFERROR(VLOOKUP(B10,'DS NGHIEP VU BO'!$A$3:$BX$148,6,0),"") -> 86022423 | E10: =VLOOKUP(B10,'DS NGHIEP VU BO'!$A$3:$BX$148,45,0) -> Vĩnh Long | F10: =IF(G10<>"","Giải thưởng kỳ thi chọn học sinh giỏi cấp tỉnh/TP:","") | G10: =IFERROR(IF(VLOOKUP(B10,'DANH SACH UEH'!$A$3:$FE$2228,18,0)="Không có","",VLOOKUP(B10,'DANH SACH UEH'!$A$3:$FE$2228,18,0)),"") | H10: =IFERROR(IF(VLOOKUP(B10,'DANH SACH UEH'!$A$3:$FE$2228,20,0)="Không có","",VLOOKUP(B10,'DANH SACH UEH'!$A$3:$FE$2228,20,0)),"") | I10: =IFERROR(IF(VLOOKUP(B10,'DANH SACH UEH'!$A$3:$FE$2228,19,0)="Không có","",VLOOKUP(B10,'DANH SACH UEH'!$A$3:$FE$2228,19,0)),"") | J10: =VLOOKUP(B10,'DANH SACH UEH'!$A$3:$FE$2228,6,0) -> 17/07/2008 | K10: =IF(VLOOKUP(B10,'DANH SACH UEH'!$A$3:$FE$2228,5,0)="1","Nữ","Nam") -> Nam | L10: =VLOOKUP(B10,'DANH SACH UEH'!$A$3:$FE$2228,14,0) -> Kinh | M10: =VLOOKUP(B10,'DANH SACH UEH'!$A$3:$FE$2228,7,0) -> luongnguyen.dat2008@gmail.com | N10: =VLOOKUP(B10,'DANH SACH UEH'!$A$3:$FE$2228,8,0) -> 0907370129 | O10: =IFERROR(VLOOKUP(AE10,'DS TAO MAIL'!$D$3:$M$1120,5,0),"") -> 31261570467 | P10: =IFERROR(VLOOKUP(AE10,'DS TAO MAIL'!$D$3:$M$1120,8,0),"") -> 24167667 | Q10: =IFERROR(VLOOKUP(AE10,'DS TAO MAIL'!$D$3:$M$1120,7,0),"") -> datluong.31261570467@st.ueh.edu.vn | R10: =IFERROR(VLOOKUP(AE10,'DS TAO MAIL'!$D$3:$M$1120,8,0),"") -> 24167667 | S10: 77.51 | U10: 68.34 | V10: =IFERROR(IF(VLOOKUP(B10,'DANH SACH UEH'!$A$3:$FE$2228,27,0)="Không có","",IF(VLOOKUP(B10,'DANH SACH UEH'!$A$3:$FE$2228,29,0)<"6","",(VLOOKUP(B10,'DANH SACH UEH'!$A$3:$FE$2228,27,0)))),"") | W10: =IFERROR(IF(VLOOKUP(B10,'DANH SACH UEH'!$A$3:$FE$2228,29,0)<"6","",VLOOKUP(B10,'DANH SACH UEH'!$A$3:$FE$2228,29,0)),"") | X10: =IFERROR(IF(V10="","",VLOOKUP(B10,'DANH SACH UEH'!$A$3:$FE$2228,28,0)&""),"") | Z10: =VLOOKUP(B10,'DANH SACH UEH'!$A$3:$FE$2228,44,0) -> 8.33 | AA10: =VLOOKUP(B10,'DANH SACH UEH'!$A$3:$FE$2228,45,0) -> 8.38 | AB10: =VLOOKUP(B10,'DANH SACH UEH'!$A$3:$FE$2228,46,0) -> 8.91 | AE10: =VLOOKUP(B10,'DANH SACH UEH'!$A$3:$I$2229,4,0) -> LƯƠNG NGUYỄN ĐẠT | AF10: =VLOOKUP(B10,'DANH SACH UEH'!$A$3:$I$2229,8,0) -> 0907370129
A11: 10 | B11: 083308010347 | C11: =VLOOKUP(B11,'DANH SACH UEH'!$A$3:$FE$2228,2,0) -> KSVBS2642750 | D11: =IFERROR(VLOOKUP(B11,'DS NGHIEP VU BO'!$A$3:$BX$148,6,0),"") -> 86011382 | E11: =VLOOKUP(B11,'DS NGHIEP VU BO'!$A$3:$BX$148,45,0) -> Vĩnh Long | F11: =IF(G11<>"","Giải thưởng kỳ thi chọn học sinh giỏi cấp tỉnh/TP:","") | G11: =IFERROR(IF(VLOOKUP(B11,'DANH SACH UEH'!$A$3:$FE$2228,18,0)="Không có","",VLOOKUP(B11,'DANH SACH UEH'!$A$3:$FE$2228,18,0)),"") | H11: =IFERROR(IF(VLOOKUP(B11,'DANH SACH UEH'!$A$3:$FE$2228,20,0)="Không có","",VLOOKUP(B11,'DANH SACH UEH'!$A$3:$FE$2228,20,0)),"") | I11: =IFERROR(IF(VLOOKUP(B11,'DANH SACH UEH'!$A$3:$FE$2228,19,0)="Không có","",VLOOKUP(B11,'DANH SACH UEH'!$A$3:$FE$2228,19,0)),"") | J11: =VLOOKUP(B11,'DANH SACH UEH'!$A$3:$FE$2228,6,0) -> 29/08/2008 | K11: =IF(VLOOKUP(B11,'DANH SACH UEH'!$A$3:$FE$2228,5,0)="1","Nữ","Nam") -> Nữ | L11: =VLOOKUP(B11,'DANH SACH UEH'!$A$3:$FE$2228,14,0) -> Kinh | M11: =VLOOKUP(B11,'DANH SACH UEH'!$A$3:$FE$2228,7,0) -> jinshu2908@gmail.com | N11: =VLOOKUP(B11,'DANH SACH UEH'!$A$3:$FE$2228,8,0) -> 0397288421 | O11: =IFERROR(VLOOKUP(AE11,'DS TAO MAIL'!$D$3:$M$1120,5,0),"") -> 31261570489 | P11: =IFERROR(VLOOKUP(AE11,'DS TAO MAIL'!$D$3:$M$1120,8,0),"") -> 51770313 | Q11: =IFERROR(VLOOKUP(AE11,'DS TAO MAIL'!$D$3:$M$1120,7,0),"") -> thunguyen.31261570489@st.ueh.edu.vn | R11: =IFERROR(VLOOKUP(AE11,'DS TAO MAIL'!$D$3:$M$1120,8,0),"") -> 51770313 | S11: 84.64 | U11: 83.54 | V11: =IFERROR(IF(VLOOKUP(B11,'DANH SACH UEH'!$A$3:$FE$2228,27,0)="Không có","",IF(VLOOKUP(B11,'DANH SACH UEH'!$A$3:$FE$2228,29,0)<"6","",(VLOOKUP(B11,'DANH SACH UEH'!$A$3:$FE$2228,27,0)))),"") | W11: =IFERROR(IF(VLOOKUP(B11,'DANH SACH UEH'!$A$3:$FE$2228,29,0)<"6","",VLOOKUP(B11,'DANH SACH UEH'!$A$3:$FE$2228,29,0)),"") | X11: =IFERROR(IF(V11="","",VLOOKUP(B11,'DANH SACH UEH'!$A$3:$FE$2228,28,0)&""),"") | Z11: =VLOOKUP(B11,'DANH SACH UEH'!$A$3:$FE$2228,44,0) -> 8.19 | AA11: =VLOOKUP(B11,'DANH SACH UEH'!$A$3:$FE$2228,45,0) -> 8.07 | AB11: =VLOOKUP(B11,'DANH SACH UEH'!$A$3:$FE$2228,46,0) -> 9.04 | AE11: =VLOOKUP(B11,'DANH SACH UEH'!$A$3:$I$2229,4,0) -> NGUYỄN THỊ KIM THƯ | AF11: =VLOOKUP(B11,'DANH SACH UEH'!$A$3:$I$2229,8,0) -> 0397288421
A12: 11 | B12: 083308001521 | C12: =VLOOKUP(B12,'DANH SACH UEH'!$A$3:$FE$2228,2,0) -> KSVBS2636260 | D12: =IFERROR(VLOOKUP(B12,'DS NGHIEP VU BO'!$A$3:$BX$148,6,0),"") -> 86004583 | E12: =VLOOKUP(B12,'DS NGHIEP VU BO'!$A$3:$BX$148,45,0) -> Vĩnh Long | F12: =IF(G12<>"","Giải thưởng kỳ thi chọn học sinh giỏi cấp tỉnh/TP:","") | G12: =IFERROR(IF(VLOOKUP(B12,'DANH SACH UEH'!$A$3:$FE$2228,18,0)="Không có","",VLOOKUP(B12,'DANH SACH UEH'!$A$3:$FE$2228,18,0)),"") | H12: =IFERROR(IF(VLOOKUP(B12,'DANH SACH UEH'!$A$3:$FE$2228,20,0)="Không có","",VLOOKUP(B12,'DANH SACH UEH'!$A$3:$FE$2228,20,0)),"") | I12: =IFERROR(IF(VLOOKUP(B12,'DANH SACH UEH'!$A$3:$FE$2228,19,0)="Không có","",VLOOKUP(B12,'DANH SACH UEH'!$A$3:$FE$2228,19,0)),"") | J12: =VLOOKUP(B12,'DANH SACH UEH'!$A$3:$FE$2228,6,0) -> 03/12/2008 | K12: =IF(VLOOKUP(B12,'DANH SACH UEH'!$A$3:$FE$2228,5,0)="1","Nữ","Nam") -> Nữ | L12: =VLOOKUP(B12,'DANH SACH UEH'!$A$3:$FE$2228,14,0) -> Kinh | M12: =VLOOKUP(B12,'DANH SACH UEH'!$A$3:$FE$2228,7,0) -> dgngocmy08@gmail.com | N12: =VLOOKUP(B12,'DANH SACH UEH'!$A$3:$FE$2228,8,0) -> 0788894298 | O12: =IFERROR(VLOOKUP(AE12,'DS TAO MAIL'!$D$3:$M$1120,5,0),"") | P12: =IFERROR(VLOOKUP(AE12,'DS TAO MAIL'!$D$3:$M$1120,8,0),"") | Q12: =IFERROR(VLOOKUP(AE12,'DS TAO MAIL'!$D$3:$M$1120,7,0),"") | R12: =IFERROR(VLOOKUP(AE12,'DS TAO MAIL'!$D$3:$M$1120,8,0),"") | S12: 73.95 | U12: 72.28 | V12: =IFERROR(IF(VLOOKUP(B12,'DANH SACH UEH'!$A$3:$FE$2228,27,0)="Không có","",IF(VLOOKUP(B12,'DANH SACH UEH'!$A$3:$FE$2228,29,0)<"6","",(VLOOKUP(B12,'DANH SACH UEH'!$A$3:$FE$2228,27,0)))),"") | W12: =IFERROR(IF(VLOOKUP(B12,'DANH SACH UEH'!$A$3:$FE$2228,29,0)<"6","",VLOOKUP(B12,'DANH SACH UEH'!$A$3:$FE$2228,29,0)),"") | X12: =IFERROR(IF(V12="","",VLOOKUP(B12,'DANH SACH UEH'!$A$3:$FE$2228,28,0)&""),"") | Z12: =VLOOKUP(B12,'DANH SACH UEH'!$A$3:$FE$2228,44,0) -> 8.11 | AA12: =VLOOKUP(B12,'DANH SACH UEH'!$A$3:$FE$2228,45,0) -> 8.40 | AB12: =VLOOKUP(B12,'DANH SACH UEH'!$A$3:$FE$2228,46,0) -> 8.48 | AE12: =VLOOKUP(B12,'DANH SACH UEH'!$A$3:$I$2229,4,0) -> ĐẶNG NGỌC MỸ | AF12: =VLOOKUP(B12,'DANH SACH UEH'!$A$3:$I$2229,8,0) -> 0788894298
A13: 12 | B13: 082208015752 | C13: =VLOOKUP(B13,'DANH SACH UEH'!$A$3:$FE$2228,2,0) -> KSVBS2624777 | D13: =IFERROR(VLOOKUP(B13,'DS NGHIEP VU BO'!$A$3:$BX$148,6,0),"") -> 82019636 | E13: =VLOOKUP(B13,'DS NGHIEP VU BO'!$A$3:$BX$148,45,0) -> Đồng Tháp | F13: =IF(G13<>"","Giải thưởng kỳ thi chọn học sinh giỏi cấp tỉnh/TP:","") | G13: =IFERROR(IF(VLOOKUP(B13,'DANH SACH UEH'!$A$3:$FE$2228,18,0)="Không có","",VLOOKUP(B13,'DANH SACH UEH'!$A$3:$FE$2228,18,0)),"") | H13: =IFERROR(IF(VLOOKUP(B13,'DANH SACH UEH'!$A$3:$FE$2228,20,0)="Không có","",VLOOKUP(B13,'DANH SACH UEH'!$A$3:$FE$2228,20,0)),"") | I13: =IFERROR(IF(VLOOKUP(B13,'DANH SACH UEH'!$A$3:$FE$2228,19,0)="Không có","",VLOOKUP(B13,'DANH SACH UEH'!$A$3:$FE$2228,19,0)),"") | J13: =VLOOKUP(B13,'DANH SACH UEH'!$A$3:$FE$2228,6,0) -> 26/10/2008 | K13: =IF(VLOOKUP(B13,'DANH SACH UEH'!$A$3:$FE$2228,5,0)="1","Nữ","Nam") -> Nam | L13: =VLOOKUP(B13,'DANH SACH UEH'!$A$3:$FE$2228,14,0) -> Kinh | M13: =VLOOKUP(B13,'DANH SACH UEH'!$A$3:$FE$2228,7,0) -> nguyenphuhao.official@gmail.com | N13: =VLOOKUP(B13,'DANH SACH UEH'!$A$3:$FE$2228,8,0) -> 0333690063 | O13: =IFERROR(VLOOKUP(AE13,'DS TAO MAIL'!$D$3:$M$1120,5,0),"") -> 31261570428 | P13: =IFERROR(VLOOKUP(AE13,'DS TAO MAIL'!$D$3:$M$1120,8,0),"") -> 50849878 | Q13: =IFERROR(VLOOKUP(AE13,'DS TAO MAIL'!$D$3:$M$1120,7,0),"") -> haonguyen.31261570428@st.ueh.edu.vn | R13: =IFERROR(VLOOKUP(AE13,'DS TAO MAIL'!$D$3:$M$1120,8,0),"") -> 50849878 | S13: 68.39 | U13: 67.56 | V13: =IFERROR(IF(VLOOKUP(B13,'DANH SACH UEH'!$A$3:$FE$2228,27,0)="Không có","",IF(VLOOKUP(B13,'DANH SACH UEH'!$A$3:$FE$2228,29,0)<"6","",(VLOOKUP(B13,'DANH SACH UEH'!$A$3:$FE$2228,27,0)))),"") | W13: =IFERROR(IF(VLOOKUP(B13,'DANH SACH UEH'!$A$3:$FE$2228,29,0)<"6","",VLOOKUP(B13,'DANH SACH UEH'!$A$3:$FE$2228,29,0)),"") | X13: =IFERROR(IF(V13="","",VLOOKUP(B13,'DANH SACH UEH'!$A$3:$FE$2228,28,0)&""),"") | Z13: =VLOOKUP(B13,'DANH SACH UEH'!$A$3:$FE$2228,44,0) -> 8.51 | AA13: =VLOOKUP(B13,'DANH SACH UEH'!$A$3:$FE$2228,45,0) -> 7.99 | AB13: =VLOOKUP(B13,'DANH SACH UEH'!$A$3:$FE$2228,46,0) -> 7.86 | AE13: =VLOOKUP(B13,'DANH SACH UEH'!$A$3:$I$2229,4,0) -> NGUYỄN PHÚ HÀO | AF13: =VLOOKUP(B13,'DANH SACH UEH'!$A$3:$I$2229,8,0) -> 0333690063
A14: 13 | B14: 079208042443 | C14: =VLOOKUP(B14,'DANH SACH UEH'!$A$3:$FE$2228,2,0) -> KSVBS2613705 | D14: =IFERROR(VLOOKUP(B14,'DS NGHIEP VU BO'!$A$3:$BX$148,6,0),"") -> 79006690 | E14: =VLOOKUP(B14,'DS NGHIEP VU BO'!$A$3:$BX$148,45,0) -> Tp. Hồ Chí Minh | F14: =IF(G14<>"","Giải thưởng kỳ thi chọn học sinh giỏi cấp tỉnh/TP:","") | G14: =IFERROR(IF(VLOOKUP(B14,'DANH SACH UEH'!$A$3:$FE$2228,18,0)="Không có","",VLOOKUP(B14,'DANH SACH UEH'!$A$3:$FE$2228,18,0)),"") | H14: =IFERROR(IF(VLOOKUP(B14,'DANH SACH UEH'!$A$3:$FE$2228,20,0)="Không có","",VLOOKUP(B14,'DANH SACH UEH'!$A$3:$FE$2228,20,0)),"") | I14: =IFERROR(IF(VLOOKUP(B14,'DANH SACH UEH'!$A$3:$FE$2228,19,0)="Không có","",VLOOKUP(B14,'DANH SACH UEH'!$A$3:$FE$2228,19,0)),"") | J14: =VLOOKUP(B14,'DANH SACH UEH'!$A$3:$FE$2228,6,0) -> 24/06/2008 | K14: =IF(VLOOKUP(B14,'DANH SACH UEH'!$A$3:$FE$2228,5,0)="1","Nữ","Nam") -> Nam | L14: =VLOOKUP(B14,'DANH SACH UEH'!$A$3:$FE$2228,14,0) -> Kinh | M14: =VLOOKUP(B14,'DANH SACH UEH'!$A$3:$FE$2228,7,0) -> huylebron123@gmail.com | N14: =VLOOKUP(B14,'DANH SACH UEH'!$A$3:$FE$2228,8,0) -> 0364155601 | O14: =IFERROR(VLOOKUP(AF14,'DS TAO MAIL'!$A$3:$M$1120,8,0),"") | P14: =IFERROR(VLOOKUP(AF14,'DS TAO MAIL'!$A$3:$M$1120,11,0),"") | Q14: =IFERROR(VLOOKUP(AF14,'DS TAO MAIL'!$A$3:$M$1120,10,0),"") | R14: =IFERROR(VLOOKUP(AF14,'DS TAO MAIL'!$A$3:$M$1120,11,0),"") | S14: 80.56 | U14: 78.4 | V14: =IFERROR(IF(VLOOKUP(B14,'DANH SACH UEH'!$A$3:$FE$2228,27,0)="Không có","",IF(VLOOKUP(B14,'DANH SACH UEH'!$A$3:$FE$2228,29,0)<"6","",(VLOOKUP(B14,'DANH SACH UEH'!$A$3:$FE$2228,27,0)))),"") -> IELTS | W14: =IFERROR(IF(VLOOKUP(B14,'DANH SACH UEH'!$A$3:$FE$2228,29,0)<"6","",VLOOKUP(B14,'DANH SACH UEH'!$A$3:$FE$2228,29,0)),"") -> 7 | X14: =IFERROR(IF(V14="","",VLOOKUP(B14,'DANH SACH UEH'!$A$3:$FE$2228,28,0)&""),"") -> 07/09/2025 | Z14: =VLOOKUP(B14,'DANH SACH UEH'!$A$3:$FE$2228,44,0) -> 9.00 | AA14: =VLOOKUP(B14,'DANH SACH UEH'!$A$3:$FE$2228,45,0) -> 9.18 | AB14: =VLOOKUP(B14,'DANH SACH UEH'!$A$3:$FE$2228,46,0) -> 8.87 | AE14: =VLOOKUP(B14,'DANH SACH UEH'!$A$3:$I$2229,4,0) -> HUỲNH MINH HUY | AF14: =VLOOKUP(B14,'DANH SACH UEH'!$A$3:$I$2229,8,0) -> 0364155601
A15: 14 | B15: 072308010254 | C15: =VLOOKUP(B15,'DANH SACH UEH'!$A$3:$FE$2228,2,0) -> KSVBS2610852 | D15: =IFERROR(VLOOKUP(B15,'DS NGHIEP VU BO'!$A$3:$BX$148,6,0),"") -> 80018209 | E15: =VLOOKUP(B15,'DS NGHIEP VU BO'!$A$3:$BX$148,45,0) -> Tây Ninh | F15: =IF(G15<>"","Giải thưởng kỳ thi chọn học sinh giỏi cấp tỉnh/TP:","") | G15: =IFERROR(IF(VLOOKUP(B15,'DANH SACH UEH'!$A$3:$FE$2228,18,0)="Không có","",VLOOKUP(B15,'DANH SACH UEH'!$A$3:$FE$2228,18,0)),"") | H15: =IFERROR(IF(VLOOKUP(B15,'DANH SACH UEH'!$A$3:$FE$2228,20,0)="Không có","",VLOOKUP(B15,'DANH SACH UEH'!$A$3:$FE$2228,20,0)),"") | I15: =IFERROR(IF(VLOOKUP(B15,'DANH SACH UEH'!$A$3:$FE$2228,19,0)="Không có","",VLOOKUP(B15,'DANH SACH UEH'!$A$3:$FE$2228,19,0)),"") | J15: =VLOOKUP(B15,'DANH SACH UEH'!$A$3:$FE$2228,6,0) -> 26/08/2008 | K15: =IF(VLOOKUP(B15,'DANH SACH UEH'!$A$3:$FE$2228,5,0)="1","Nữ","Nam") -> Nam | L15: =VLOOKUP(B15,'DANH SACH UEH'!$A$3:$FE$2228,14,0) -> Kinh | M15: =VLOOKUP(B15,'DANH SACH UEH'!$A$3:$FE$2228,7,0) -> lethanhnga.tn2020@gmail.com | N15: =VLOOKUP(B15,'DANH SACH UEH'!$A$3:$FE$2228,8,0) -> 0929499740 | O15: =IFERROR(VLOOKUP(AE15,'DS TAO MAIL'!$D$3:$M$1120,5,0),"") -> 31261570452 | P15: =IFERROR(VLOOKUP(AE15,'DS TAO MAIL'!$D$3:$M$1120,8,0),"") -> 51079038 | Q15: =IFERROR(VLOOKUP(AE15,'DS TAO MAIL'!$D$3:$M$1120,7,0),"") -> hannguyen.31261570452@st.ueh.edu.vn | R15: =IFERROR(VLOOKUP(AE15,'DS TAO MAIL'!$D$3:$M$1120,8,0),"") -> 51079038 | S15: 78.46 | U15: 77.72 | V15: =IFERROR(IF(VLOOKUP(B15,'DANH SACH UEH'!$A$3:$FE$2228,27,0)="Không có","",IF(VLOOKUP(B15,'DANH SACH UEH'!$A$3:$FE$2228,29,0)<"6","",(VLOOKUP(B15,'DANH SACH UEH'!$A$3:$FE$2228,27,0)))),"") | W15: =IFERROR(IF(VLOOKUP(B15,'DANH SACH UEH'!$A$3:$FE$2228,29,0)<"6","",VLOOKUP(B15,'DANH SACH UEH'!$A$3:$FE$2228,29,0)),"") | X15: =IFERROR(IF(V15="","",VLOOKUP(B15,'DANH SACH UEH'!$A$3:$FE$2228,28,0)&""),"") | Z15: =VLOOKUP(B15,'DANH SACH UEH'!$A$3:$FE$2228,44,0) -> 7.70 | AA15: =VLOOKUP(B15,'DANH SACH UEH'!$A$3:$FE$2228,45,0) -> 7.76 | AB15: =VLOOKUP(B15,'DANH SACH UEH'!$A$3:$FE$2228,46,0) -> 8.31 | AE15: =VLOOKUP(B15,'DANH SACH UEH'!$A$3:$I$2229,4,0) -> NGUYỄN LÊ NGỌC HÂN | AF15: =VLOOKUP(B15,'DANH SACH UEH'!$A$3:$I$2229,8,0) -> 0929499740
A16: 15 | B16: 066308006122 | C16: =VLOOKUP(B16,'DANH SACH UEH'!$A$3:$FE$2228,2,0) -> KSVBS2611188 | D16: =IFERROR(VLOOKUP(B16,'DS NGHIEP VU BO'!$A$3:$BX$148,6,0),"") -> 66010126 | E16: =VLOOKUP(B16,'DS NGHIEP VU BO'!$A$3:$BX$148,45,0) -> Đắk Lắk | F16: =IF(G16<>"","Giải thưởng kỳ thi chọn học sinh giỏi cấp tỉnh/TP:","") | G16: =IFERROR(IF(VLOOKUP(B16,'DANH SACH UEH'!$A$3:$FE$2228,18,0)="Không có","",VLOOKUP(B16,'DANH SACH UEH'!$A$3:$FE$2228,18,0)),"") | H16: =IFERROR(IF(VLOOKUP(B16,'DANH SACH UEH'!$A$3:$FE$2228,20,0)="Không có","",VLOOKUP(B16,'DANH SACH UEH'!$A$3:$FE$2228,20,0)),"") | I16: =IFERROR(IF(VLOOKUP(B16,'DANH SACH UEH'!$A$3:$FE$2228,19,0)="Không có","",VLOOKUP(B16,'DANH SACH UEH'!$A$3:$FE$2228,19,0)),"") | J16: =VLOOKUP(B16,'DANH SACH UEH'!$A$3:$FE$2228,6,0) -> 25/07/2008 | K16: =IF(VLOOKUP(B16,'DANH SACH UEH'!$A$3:$FE$2228,5,0)="1","Nữ","Nam") -> Nữ | L16: =VLOOKUP(B16,'DANH SACH UEH'!$A$3:$FE$2228,14,0) -> Sán chay (Cao Lan, Sán Chỉ) | M16: =VLOOKUP(B16,'DANH SACH UEH'!$A$3:$FE$2228,7,0) -> lythigiangmy008@gmail.com | N16: =VLOOKUP(B16,'DANH SACH UEH'!$A$3:$FE$2228,8,0) -> 0896540820 | O16: =IFERROR(VLOOKUP(AE16,'DS TAO MAIL'!$D$3:$M$1120,5,0),"") -> 31261570535 | P16: =IFERROR(VLOOKUP(AE16,'DS TAO MAIL'!$D$3:$M$1120,8,0),"") -> 98942758 | Q16: =IFERROR(VLOOKUP(AE16,'DS TAO MAIL'!$D$3:$M$1120,7,0),"") -> myly.31261570535@st.ueh.edu.vn | R16: =IFERROR(VLOOKUP(AE16,'DS TAO MAIL'!$D$3:$M$1120,8,0),"") -> 98942758 | S16: 82.02 | U16: 81.4 | V16: =IFERROR(IF(VLOOKUP(B16,'DANH SACH UEH'!$A$3:$FE$2228,27,0)="Không có","",IF(VLOOKUP(B16,'DANH SACH UEH'!$A$3:$FE$2228,29,0)<"6","",(VLOOKUP(B16,'DANH SACH UEH'!$A$3:$FE$2228,27,0)))),"") | W16: =IFERROR(IF(VLOOKUP(B16,'DANH SACH UEH'!$A$3:$FE$2228,29,0)<"6","",VLOOKUP(B16,'DANH SACH UEH'!$A$3:$FE$2228,29,0)),"") | X16: =IFERROR(IF(V16="","",VLOOKUP(B16,'DANH SACH UEH'!$A$3:$FE$2228,28,0)&""),"") | Z16: =VLOOKUP(B16,'DANH SACH UEH'!$A$3:$FE$2228,44,0) -> 7.63 | AA16: =VLOOKUP(B16,'DANH SACH UEH'!$A$3:$FE$2228,45,0) -> 8.05 | AB16: =VLOOKUP(B16,'DANH SACH UEH'!$A$3:$FE$2228,46,0) -> 8.51 | AE16: =VLOOKUP(B16,'DANH SACH UEH'!$A$3:$I$2229,4,0) -> LÝ THỊ GIÁNG MY | AF16: =VLOOKUP(B16,'DANH SACH UEH'!$A$3:$I$2229,8,0) -> 0896540820
A17: 16 | B17: 044208010722 | C17: =VLOOKUP(B17,'DANH SACH UEH'!$A$3:$FE$2228,2,0) -> KSVBS2642702 | D17: =IFERROR(VLOOKUP(B17,'DS NGHIEP VU BO'!$A$3:$BX$148,6,0),"") -> 44010909 | E17: =VLOOKUP(B17,'DS NGHIEP VU BO'!$A$3:$BX$148,45,0) -> Quảng Trị | F17: =IF(G17<>"","Giải thưởng kỳ thi chọn học sinh giỏi cấp tỉnh/TP:","") | G17: =IFERROR(IF(VLOOKUP(B17,'DANH SACH UEH'!$A$3:$FE$2228,18,0)="Không có","",VLOOKUP(B17,'DANH SACH UEH'!$A$3:$FE$2228,18,0)),"") | H17: =IFERROR(IF(VLOOKUP(B17,'DANH SACH UEH'!$A$3:$FE$2228,20,0)="Không có","",VLOOKUP(B17,'DANH SACH UEH'!$A$3:$FE$2228,20,0)),"") | I17: =IFERROR(IF(VLOOKUP(B17,'DANH SACH UEH'!$A$3:$FE$2228,19,0)="Không có","",VLOOKUP(B17,'DANH SACH UEH'!$A$3:$FE$2228,19,0)),"") | J17: =VLOOKUP(B17,'DANH SACH UEH'!$A$3:$FE$2228,6,0) -> 03/05/2008 | K17: =IF(VLOOKUP(B17,'DANH SACH UEH'!$A$3:$FE$2228,5,0)="1","Nữ","Nam") -> Nam | L17: =VLOOKUP(B17,'DANH SACH UEH'!$A$3:$FE$2228,14,0) -> Kinh | M17: =VLOOKUP(B17,'DANH SACH UEH'!$A$3:$FE$2228,7,0) -> lehongquan0508@gmail.com | N17: =VLOOKUP(B17,'DANH SACH UEH'!$A$3:$FE$2228,8,0) -> 0919747978 | O17: =IFERROR(VLOOKUP(AE17,'DS TAO MAIL'!$D$3:$M$1120,5,0),"") -> 31261570526 | P17: =IFERROR(VLOOKUP(AE17,'DS TAO MAIL'!$D$3:$M$1120,8,0),"") -> 40169828 | Q17: =IFERROR(VLOOKUP(AE17,'DS TAO MAIL'!$D$3:$M$1120,7,0),"") -> quanle.31261570526@st.ueh.edu.vn | R17: =IFERROR(VLOOKUP(AE17,'DS TAO MAIL'!$D$3:$M$1120,8,0),"") -> 40169828 | S17: 76.22 | U17: 76.22 | V17: =IFERROR(IF(VLOOKUP(B17,'DANH SACH UEH'!$A$3:$FE$2228,27,0)="Không có","",IF(VLOOKUP(B17,'DANH SACH UEH'!$A$3:$FE$2228,29,0)<"6","",(VLOOKUP(B17,'DANH SACH UEH'!$A$3:$FE$2228,27,0)))),"") -> IELTS | W17: =IFERROR(IF(VLOOKUP(B17,'DANH SACH UEH'!$A$3:$FE$2228,29,0)<"6","",VLOOKUP(B17,'DANH SACH UEH'!$A$3:$FE$2228,29,0)),"") -> 6.5 | X17: =IFERROR(IF(V17="","",VLOOKUP(B17,'DANH SACH UEH'!$A$3:$FE$2228,28,0)&""),"") -> 30/08/2025 | Z17: =VLOOKUP(B17,'DANH SACH UEH'!$A$3:$FE$2228,44,0) -> 8.47 | AA17: =VLOOKUP(B17,'DANH SACH UEH'!$A$3:$FE$2228,45,0) -> 8.37 | AB17: =VLOOKUP(B17,'DANH SACH UEH'!$A$3:$FE$2228,46,0) -> 8.11 | AE17: =VLOOKUP(B17,'DANH SACH UEH'!$A$3:$I$2229,4,0) -> LÊ HỒNG QUÂN | AF17: =VLOOKUP(B17,'DANH SACH UEH'!$A$3:$I$2229,8,0) -> 0919747978
A18: 17 | B18: 040208024160 | C18: =VLOOKUP(B18,'DANH SACH UEH'!$A$3:$FE$2228,2,0) -> KSVBS2623414 | D18: =IFERROR(VLOOKUP(B18,'DS NGHIEP VU BO'!$A$3:$BX$148,6,0),"") -> 40029525 | E18: =VLOOKUP(B18,'DS NGHIEP VU BO'!$A$3:$BX$148,45,0) -> Nghệ An | F18: =IF(G18<>"","Giải thưởng kỳ thi chọn học sinh giỏi cấp tỉnh/TP:","") | G18: =IFERROR(IF(VLOOKUP(B18,'DANH SACH UEH'!$A$3:$FE$2228,18,0)="Không có","",VLOOKUP(B18,'DANH SACH UEH'!$A$3:$FE$2228,18,0)),"") | H18: =IFERROR(IF(VLOOKUP(B18,'DANH SACH UEH'!$A$3:$FE$2228,20,0)="Không có","",VLOOKUP(B18,'DANH SACH UEH'!$A$3:$FE$2228,20,0)),"") | I18: =IFERROR(IF(VLOOKUP(B18,'DANH SACH UEH'!$A$3:$FE$2228,19,0)="Không có","",VLOOKUP(B18,'DANH SACH UEH'!$A$3:$FE$2228,19,0)),"") | J18: =VLOOKUP(B18,'DANH SACH UEH'!$A$3:$FE$2228,6,0) -> 09/07/2008 | K18: =IF(VLOOKUP(B18,'DANH SACH UEH'!$A$3:$FE$2228,5,0)="1","Nữ","Nam") -> Nam | L18: =VLOOKUP(B18,'DANH SACH UEH'!$A$3:$FE$2228,14,0) -> Kinh | M18: =VLOOKUP(B18,'DANH SACH UEH'!$A$3:$FE$2228,7,0) -> nguyengiaanhhieu2k8@gmail.com | N18: =VLOOKUP(B18,'DANH SACH UEH'!$A$3:$FE$2228,8,0) -> 0569619450 | O18: =IFERROR(VLOOKUP(AE18,'DS TAO MAIL'!$D$3:$M$1120,5,0),"") -> 31261570533 | P18: =IFERROR(VLOOKUP(AE18,'DS TAO MAIL'!$D$3:$M$1120,8,0),"") -> 24085537 | Q18: =IFERROR(VLOOKUP(AE18,'DS TAO MAIL'!$D$3:$M$1120,7,0),"") -> hieunguyen.31261570533@st.ueh.edu.vn | R18: =IFERROR(VLOOKUP(AE18,'DS TAO MAIL'!$D$3:$M$1120,8,0),"") -> 24085537 | S18: 67.49 | U18: 66.66 | V18: =IFERROR(IF(VLOOKUP(B18,'DANH SACH UEH'!$A$3:$FE$2228,27,0)="Không có","",IF(VLOOKUP(B18,'DANH SACH UEH'!$A$3:$FE$2228,29,0)<"6","",(VLOOKUP(B18,'DANH SACH UEH'!$A$3:$FE$2228,27,0)))),"") | W18: =IFERROR(IF(VLOOKUP(B18,'DANH SACH UEH'!$A$3:$FE$2228,29,0)<"6","",VLOOKUP(B18,'DANH SACH UEH'!$A$3:$FE$2228,29,0)),"") | X18: =IFERROR(IF(V18="","",VLOOKUP(B18,'DANH SACH UEH'!$A$3:$FE$2228,28,0)&""),"") | Z18: =VLOOKUP(B18,'DANH SACH UEH'!$A$3:$FE$2228,44,0) -> 8.66 | AA18: =VLOOKUP(B18,'DANH SACH UEH'!$A$3:$FE$2228,45,0) -> 8.91 | AB18: =VLOOKUP(B18,'DANH SACH UEH'!$A$3:$FE$2228,46,0) -> 8.82 | AE18: =VLOOKUP(B18,'DANH SACH UEH'!$A$3:$I$2229,4,0) -> NGUYỄN GIA ANH HIẾU | AF18: =VLOOKUP(B18,'DANH SACH UEH'!$A$3:$I$2229,8,0) -> 0569619450
A19: 18 | B19: 038208002727 | C19: =VLOOKUP(B19,'DANH SACH UEH'!$A$3:$FE$2228,2,0) -> KSVBS2626461 | D19: =IFERROR(VLOOKUP(B19,'DS NGHIEP VU BO'!$A$3:$BX$148,6,0),"") -> 68024623 | E19: =VLOOKUP(B19,'DS NGHIEP VU BO'!$A$3:$BX$148,45,0) -> Lâm Đồng | F19: =IF(G19<>"","Giải thưởng kỳ thi chọn học sinh giỏi cấp tỉnh/TP:","") | G19: =IFERROR(IF(VLOOKUP(B19,'DANH SACH UEH'!$A$3:$FE$2228,18,0)="Không có","",VLOOKUP(B19,'DANH SACH UEH'!$A$3:$FE$2228,18,0)),"") | H19: =IFERROR(IF(VLOOKUP(B19,'DANH SACH UEH'!$A$3:$FE$2228,20,0)="Không có","",VLOOKUP(B19,'DANH SACH UEH'!$A$3:$FE$2228,20,0)),"") | I19: =IFERROR(IF(VLOOKUP(B19,'DANH SACH UEH'!$A$3:$FE$2228,19,0)="Không có","",VLOOKUP(B19,'DANH SACH UEH'!$A$3:$FE$2228,19,0)),"") | J19: =VLOOKUP(B19,'DANH SACH UEH'!$A$3:$FE$2228,6,0) -> 09/05/2008 | K19: =IF(VLOOKUP(B19,'DANH SACH UEH'!$A$3:$FE$2228,5,0)="1","Nữ","Nam") -> Nam | L19: =VLOOKUP(B19,'DANH SACH UEH'!$A$3:$FE$2228,14,0) -> Kinh | M19: =VLOOKUP(B19,'DANH SACH UEH'!$A$3:$FE$2228,7,0) -> nguyenvux95@gmail.com | N19: =VLOOKUP(B19,'DANH SACH UEH'!$A$3:$FE$2228,8,0) -> 0382731611 | O19: =IFERROR(VLOOKUP(AE19,'DS TAO MAIL'!$D$3:$M$1120,5,0),"") -> 31261570520 | P19: =IFERROR(VLOOKUP(AE19,'DS TAO MAIL'!$D$3:$M$1120,8,0),"") -> 68327293 | Q19: =IFERROR(VLOOKUP(AE19,'DS TAO MAIL'!$D$3:$M$1120,7,0),"") -> vunguyen.31261570520@st.ueh.edu.vn | R19: =IFERROR(VLOOKUP(AE19,'DS TAO MAIL'!$D$3:$M$1120,8,0),"") -> 68327293 | S19: 75.77 | U19: 74.1 | V19: =IFERROR(IF(VLOOKUP(B19,'DANH SACH UEH'!$A$3:$FE$2228,27,0)="Không có","",IF(VLOOKUP(B19,'DANH SACH UEH'!$A$3:$FE$2228,29,0)<"6","",(VLOOKUP(B19,'DANH SACH UEH'!$A$3:$FE$2228,27,0)))),"") | W19: =IFERROR(IF(VLOOKUP(B19,'DANH SACH UEH'!$A$3:$FE$2228,29,0)<"6","",VLOOKUP(B19,'DANH SACH UEH'!$A$3:$FE$2228,29,0)),"") | X19: =IFERROR(IF(V19="","",VLOOKUP(B19,'DANH SACH UEH'!$A$3:$FE$2228,28,0)&""),"") | Z19: =VLOOKUP(B19,'DANH SACH UEH'!$A$3:$FE$2228,44,0) -> 6.36 | AA19: =VLOOKUP(B19,'DANH SACH UEH'!$A$3:$FE$2228,45,0) -> 6.37 | AB19: =VLOOKUP(B19,'DANH SACH UEH'!$A$3:$FE$2228,46,0) -> 7.22 | AE19: =VLOOKUP(B19,'DANH SACH UEH'!$A$3:$I$2229,4,0) -> NGUYỄN TRUNG VŨ | AF19: =VLOOKUP(B19,'DANH SACH UEH'!$A$3:$I$2229,8,0) -> 0382731611
A20: 19 | B20: 008308006425 | C20: =VLOOKUP(B20,'DANH SACH UEH'!$A$3:$FE$2228,2,0) -> KSVBS2617443 | D20: =IFERROR(VLOOKUP(B20,'DS NGHIEP VU BO'!$A$3:$BX$148,6,0),"") -> 08016541 | E20: =VLOOKUP(B20,'DS NGHIEP VU BO'!$A$3:$BX$148,45,0) -> Tuyên Quang | F20: =IF(G20<>"","Giải thưởng kỳ thi chọn học sinh giỏi cấp tỉnh/TP:","") -> Giải thưởng kỳ thi chọn học sinh giỏi cấp tỉnh/TP: | G20: =IFERROR(IF(VLOOKUP(B20,'DANH SACH UEH'!$A$3:$FE$2228,18,0)="Không có","",VLOOKUP(B20,'DANH SACH UEH'!$A$3:$FE$2228,18,0)),"") -> Sinh học | H20: =IFERROR(IF(VLOOKUP(B20,'DANH SACH UEH'!$A$3:$FE$2228,20,0)="Không có","",VLOOKUP(B20,'DANH SACH UEH'!$A$3:$FE$2228,20,0)),"") -> Ba | I20: =IFERROR(IF(VLOOKUP(B20,'DANH SACH UEH'!$A$3:$FE$2228,19,0)="Không có","",VLOOKUP(B20,'DANH SACH UEH'!$A$3:$FE$2228,19,0)),"") -> 2025 | J20: =VLOOKUP(B20,'DANH SACH UEH'!$A$3:$FE$2228,6,0) -> 08/01/2008 | K20: =IF(VLOOKUP(B20,'DANH SACH UEH'!$A$3:$FE$2228,5,0)="1","Nữ","Nam") -> Nữ | L20: =VLOOKUP(B20,'DANH SACH UEH'!$A$3:$FE$2228,14,0) -> Kinh | M20: =VLOOKUP(B20,'DANH SACH UEH'!$A$3:$FE$2228,7,0) -> nhiv91608@gmail.com | N20: =VLOOKUP(B20,'DANH SACH UEH'!$A$3:$FE$2228,8,0) -> 0367711616 | O20: =IFERROR(VLOOKUP(AE20,'DS TAO MAIL'!$D$3:$M$1120,5,0),"") | P20: =IFERROR(VLOOKUP(AE20,'DS TAO MAIL'!$D$3:$M$1120,8,0),"") | Q20: =IFERROR(VLOOKUP(AE20,'DS TAO MAIL'!$D$3:$M$1120,7,0),"") | R20: =IFERROR(VLOOKUP(AE20,'DS TAO MAIL'!$D$3:$M$1120,8,0),"") | S20: 62.87 | U20: 62.04 | V20: =IFERROR(IF(VLOOKUP(B20,'DANH SACH UEH'!$A$3:$FE$2228,27,0)="Không có","",IF(VLOOKUP(B20,'DANH SACH UEH'!$A$3:$FE$2228,29,0)<"6","",(VLOOKUP(B20,'DANH SACH UEH'!$A$3:$FE$2228,27,0)))),"") | W20: =IFERROR(IF(VLOOKUP(B20,'DANH SACH UEH'!$A$3:$FE$2228,29,0)<"6","",VLOOKUP(B20,'DANH SACH UEH'!$A$3:$FE$2228,29,0)),"") | X20: =IFERROR(IF(V20="","",VLOOKUP(B20,'DANH SACH UEH'!$A$3:$FE$2228,28,0)&""),"") | Z20: =VLOOKUP(B20,'DANH SACH UEH'!$A$3:$FE$2228,44,0) -> 8.46 | AA20: =VLOOKUP(B20,'DANH SACH UEH'!$A$3:$FE$2228,45,0) -> 8.50 | AB20: =VLOOKUP(B20,'DANH SACH UEH'!$A$3:$FE$2228,46,0) -> 8.72 | AE20: =VLOOKUP(B20,'DANH SACH UEH'!$A$3:$I$2229,4,0) -> VŨ YẾN NHI | AF20: =VLOOKUP(B20,'DANH SACH UEH'!$A$3:$I$2229,8,0) -> 0367711616
A21: 20 | B21: 025308012169 | C21: =VLOOKUP(B21,'DANH SACH UEH'!$A$3:$FE$2228,2,0) -> KSVBS2629385 | D21: =IFERROR(VLOOKUP(B21,'DS NGHIEP VU BO'!$A$3:$BX$148,6,0),"") -> 25037325 | E21: =VLOOKUP(B21,'DS NGHIEP VU BO'!$A$3:$BX$148,45,0) -> Phú Thọ | F21: =IF(G21<>"","Giải thưởng kỳ thi chọn học sinh giỏi cấp tỉnh/TP:","") | G21: =IFERROR(IF(VLOOKUP(B21,'DANH SACH UEH'!$A$3:$FE$2228,18,0)="Không có","",VLOOKUP(B21,'DANH SACH UEH'!$A$3:$FE$2228,18,0)),"") | H21: =IFERROR(IF(VLOOKUP(B21,'DANH SACH UEH'!$A$3:$FE$2228,20,0)="Không có","",VLOOKUP(B21,'DANH SACH UEH'!$A$3:$FE$2228,20,0)),"") | I21: =IFERROR(IF(VLOOKUP(B21,'DANH SACH UEH'!$A$3:$FE$2228,19,0)="Không có","",VLOOKUP(B21,'DANH SACH UEH'!$A$3:$FE$2228,19,0)),"") | J21: =VLOOKUP(B21,'DANH SACH UEH'!$A$3:$FE$2228,6,0) -> 08/12/2008 | K21: =IF(VLOOKUP(B21,'DANH SACH UEH'!$A$3:$FE$2228,5,0)="1","Nữ","Nam") -> Nữ | L21: =VLOOKUP(B21,'DANH SACH UEH'!$A$3:$FE$2228,14,0) -> Kinh | M21: =VLOOKUP(B21,'DANH SACH UEH'!$A$3:$FE$2228,7,0) -> khanhchi8812@gmail.com | N21: =VLOOKUP(B21,'DANH SACH UEH'!$A$3:$FE$2228,8,0) -> 0327399812 | O21: =IFERROR(VLOOKUP(AE21,'DS TAO MAIL'!$D$3:$M$1120,5,0),"") -> 31261570488 | P21: =IFERROR(VLOOKUP(AE21,'DS TAO MAIL'!$D$3:$M$1120,8,0),"") -> 27522792 | Q21: =IFERROR(VLOOKUP(AE21,'DS TAO MAIL'!$D$3:$M$1120,7,0),"") -> chinguyen.31261570488@st.ueh.edu.vn | R21: =IFERROR(VLOOKUP(AE21,'DS TAO MAIL'!$D$3:$M$1120,8,0),"") -> 27522792 | S21: 64.67 | U21: 63 | V21: =IFERROR(IF(VLOOKUP(B21,'DANH SACH UEH'!$A$3:$FE$2228,27,0)="Không có","",IF(VLOOKUP(B21,'DANH SACH UEH'!$A$3:$FE$2228,29,0)<"6","",(VLOOKUP(B21,'DANH SACH UEH'!$A$3:$FE$2228,27,0)))),"") | W21: =IFERROR(IF(VLOOKUP(B21,'DANH SACH UEH'!$A$3:$FE$2228,29,0)<"6","",VLOOKUP(B21,'DANH SACH UEH'!$A$3:$FE$2228,29,0)),"") | X21: =IFERROR(IF(V21="","",VLOOKUP(B21,'DANH SACH UEH'!$A$3:$FE$2228,28,0)&""),"") | Z21: =VLOOKUP(B21,'DANH SACH UEH'!$A$3:$FE$2228,44,0) -> 8.62 | AA21: =VLOOKUP(B21,'DANH SACH UEH'!$A$3:$FE$2228,45,0) -> 8.69 | AB21: =VLOOKUP(B21,'DANH SACH UEH'!$A$3:$FE$2228,46,0) -> 9.19 | AE21: =VLOOKUP(B21,'DANH SACH UEH'!$A$3:$I$2229,4,0) -> NGUYỄN KHÁNH CHI | AF21: =VLOOKUP(B21,'DANH SACH UEH'!$A$3:$I$2229,8,0) -> 0327399812
A22: 21 | B22: 033308007672 | C22: =VLOOKUP(B22,'DANH SACH UEH'!$A$3:$FE$2228,2,0) -> KSVBS2621873 | D22: =IFERROR(VLOOKUP(B22,'DS NGHIEP VU BO'!$A$3:$BX$148,6,0),"") -> 33005334 | E22: =VLOOKUP(B22,'DS NGHIEP VU BO'!$A$3:$BX$148,45,0) -> Hưng Yên | F22: =IF(G22<>"","Giải thưởng kỳ thi chọn học sinh giỏi cấp tỉnh/TP:","") | G22: =IFERROR(IF(VLOOKUP(B22,'DANH SACH UEH'!$A$3:$FE$2228,18,0)="Không có","",VLOOKUP(B22,'DANH SACH UEH'!$A$3:$FE$2228,18,0)),"") | H22: =IFERROR(IF(VLOOKUP(B22,'DANH SACH UEH'!$A$3:$FE$2228,20,0)="Không có","",VLOOKUP(B22,'DANH SACH UEH'!$A$3:$FE$2228,20,0)),"") | I22: =IFERROR(IF(VLOOKUP(B22,'DANH SACH UEH'!$A$3:$FE$2228,19,0)="Không có","",VLOOKUP(B22,'DANH SACH UEH'!$A$3:$FE$2228,19,0)),"") | J22: =VLOOKUP(B22,'DANH SACH UEH'!$A$3:$FE$2228,6,0) -> 20/04/2008 | K22: =IF(VLOOKUP(B22,'DANH SACH UEH'!$A$3:$FE$2228,5,0)="1","Nữ","Nam") -> Nữ | L22: =VLOOKUP(B22,'DANH SACH UEH'!$A$3:$FE$2228,14,0) -> Kinh | M22: =VLOOKUP(B22,'DANH SACH UEH'!$A$3:$FE$2228,7,0) -> nhhang2@gmail.com | N22: =VLOOKUP(B22,'DANH SACH UEH'!$A$3:$FE$2228,8,0) -> 0972505985 | O22: =IFERROR(VLOOKUP(AF22,'DS TAO MAIL'!$A$3:$M$1120,8,0),"") -> 31261570513 | P22: =IFERROR(VLOOKUP(AF22,'DS TAO MAIL'!$A$3:$M$1120,11,0),"") -> 87102618 | Q22: =IFERROR(VLOOKUP(AF22,'DS TAO MAIL'!$A$3:$M$1120,10,0),"") -> hangnguyen.31261570513@st.ueh.edu.vn | R22: =IFERROR(VLOOKUP(AF22,'DS TAO MAIL'!$A$3:$M$1120,11,0),"") -> 87102618 | S22: 66.15 | U22: 64.48 | V22: =IFERROR(IF(VLOOKUP(B22,'DANH SACH UEH'!$A$3:$FE$2228,27,0)="Không có","",IF(VLOOKUP(B22,'DANH SACH UEH'!$A$3:$FE$2228,29,0)<"6","",(VLOOKUP(B22,'DANH SACH UEH'!$A$3:$FE$2228,27,0)))),"") | W22: =IFERROR(IF(VLOOKUP(B22,'DANH SACH UEH'!$A$3:$FE$2228,29,0)<"6","",VLOOKUP(B22,'DANH SACH UEH'!$A$3:$FE$2228,29,0)),"") | X22: =IFERROR(IF(V22="","",VLOOKUP(B22,'DANH SACH UEH'!$A$3:$FE$2228,28,0)&""),"") | Z22: =VLOOKUP(B22,'DANH SACH UEH'!$A$3:$FE$2228,44,0) -> 8.59 | AA22: =VLOOKUP(B22,'DANH SACH UEH'!$A$3:$FE$2228,45,0) -> 8.52 | AB22: =VLOOKUP(B22,'DANH SACH UEH'!$A$3:$FE$2228,46,0) -> 8.66 | AE22: =VLOOKUP(B22,'DANH SACH UEH'!$A$3:$I$2229,4,0) -> NGUYỄN THU HẰNG | AF22: =VLOOKUP(B22,'DANH SACH UEH'!$A$3:$I$2229,8,0) -> 0972505985
A23: 22 | B23: 034308005716 | C23: =VLOOKUP(B23,'DANH SACH UEH'!$A$3:$FE$2228,2,0) -> KSVBS2626874 | D23: =IFERROR(VLOOKUP(B23,'DS NGHIEP VU BO'!$A$3:$BX$148,6,0),"") -> 31021165 | E23: =VLOOKUP(B23,'DS NGHIEP VU BO'!$A$3:$BX$148,45,0) -> Hải Phòng | F23: =IF(G23<>"","Giải thưởng kỳ thi chọn học sinh giỏi cấp tỉnh/TP:","") | G23: =IFERROR(IF(VLOOKUP(B23,'DANH SACH UEH'!$A$3:$FE$2228,18,0)="Không có","",VLOOKUP(B23,'DANH SACH UEH'!$A$3:$FE$2228,18,0)),"") | H23: =IFERROR(IF(VLOOKUP(B23,'DANH SACH UEH'!$A$3:$FE$2228,20,0)="Không có","",VLOOKUP(B23,'DANH SACH UEH'!$A$3:$FE$2228,20,0)),"") | I23: =IFERROR(IF(VLOOKUP(B23,'DANH SACH UEH'!$A$3:$FE$2228,19,0)="Không có","",VLOOKUP(B23,'DANH SACH UEH'!$A$3:$FE$2228,19,0)),"") | J23: =VLOOKUP(B23,'DANH SACH UEH'!$A$3:$FE$2228,6,0) -> 25/10/2008 | K23: =IF(VLOOKUP(B23,'DANH SACH UEH'!$A$3:$FE$2228,5,0)="1","Nữ","Nam") -> Nữ | L23: =VLOOKUP(B23,'DANH SACH UEH'!$A$3:$FE$2228,14,0) -> Kinh | M23: =VLOOKUP(B23,'DANH SACH UEH'!$A$3:$FE$2228,7,0) -> lphuong25102008@gmail.com | N23: =VLOOKUP(B23,'DANH SACH UEH'!$A$3:$FE$2228,8,0) -> 0705796418 | O23: =IFERROR(VLOOKUP(AE23,'DS TAO MAIL'!$D$3:$M$1120,5,0),"") -> 31261570490 | P23: =IFERROR(VLOOKUP(AE23,'DS TAO MAIL'!$D$3:$M$1120,8,0),"") -> 97019616 | Q23: =IFERROR(VLOOKUP(AE23,'DS TAO MAIL'!$D$3:$M$1120,7,0),"") -> phuongnguyen.31261570490@st.ueh.edu.vn | R23: =IFERROR(VLOOKUP(AE23,'DS TAO MAIL'!$D$3:$M$1120,8,0),"") -> 97019616 | S23: 65.47 | U23: 64.64 | V23: =IFERROR(IF(VLOOKUP(B23,'DANH SACH UEH'!$A$3:$FE$2228,27,0)="Không có","",IF(VLOOKUP(B23,'DANH SACH UEH'!$A$3:$FE$2228,29,0)<"6","",(VLOOKUP(B23,'DANH SACH UEH'!$A$3:$FE$2228,27,0)))),"") | W23: =IFERROR(IF(VLOOKUP(B23,'DANH SACH UEH'!$A$3:$FE$2228,29,0)<"6","",VLOOKUP(B23,'DANH SACH UEH'!$A$3:$FE$2228,29,0)),"") | X23: =IFERROR(IF(V23="","",VLOOKUP(B23,'DANH SACH UEH'!$A$3:$FE$2228,28,0)&""),"") | Z23: =VLOOKUP(B23,'DANH SACH UEH'!$A$3:$FE$2228,44,0) -> 8.68 | AA23: =VLOOKUP(B23,'DANH SACH UEH'!$A$3:$FE$2228,45,0) -> 8.11 | AB23: =VLOOKUP(B23,'DANH SACH UEH'!$A$3:$FE$2228,46,0) -> 8.93 | AE23: =VLOOKUP(B23,'DANH SACH UEH'!$A$3:$I$2229,4,0) -> NGUYỄN LAN PHƯƠNG | AF23: =VLOOKUP(B23,'DANH SACH UEH'!$A$3:$I$2229,8,0) -> 0705796418
A24: 23 | B24: 037308003748 | C24: =VLOOKUP(B24,'DANH SACH UEH'!$A$3:$FE$2228,2,0) -> KSVBS2603312 | D24: =IFERROR(VLOOKUP(B24,'DS NGHIEP VU BO'!$A$3:$BX$148,6,0),"") -> 37003959 | E24: =VLOOKUP(B24,'DS NGHIEP VU BO'!$A$3:$BX$148,45,0) -> Ninh Bình | F24: =IF(G24<>"","Giải thưởng kỳ thi chọn học sinh giỏi cấp tỉnh/TP:","") | G24: =IFERROR(IF(VLOOKUP(B24,'DANH SACH UEH'!$A$3:$FE$2228,18,0)="Không có","",VLOOKUP(B24,'DANH SACH UEH'!$A$3:$FE$2228,18,0)),"") | H24: =IFERROR(IF(VLOOKUP(B24,'DANH SACH UEH'!$A$3:$FE$2228,20,0)="Không có","",VLOOKUP(B24,'DANH SACH UEH'!$A$3:$FE$2228,20,0)),"") | I24: =IFERROR(IF(VLOOKUP(B24,'DANH SACH UEH'!$A$3:$FE$2228,19,0)="Không có","",VLOOKUP(B24,'DANH SACH UEH'!$A$3:$FE$2228,19,0)),"") | J24: =VLOOKUP(B24,'DANH SACH UEH'!$A$3:$FE$2228,6,0) -> 27/02/2008 | K24: =IF(VLOOKUP(B24,'DANH SACH UEH'!$A$3:$FE$2228,5,0)="1","Nữ","Nam") -> Nữ | L24: =VLOOKUP(B24,'DANH SACH UEH'!$A$3:$FE$2228,14,0) -> Kinh | M24: =VLOOKUP(B24,'DANH SACH UEH'!$A$3:$FE$2228,7,0) -> phamlinh2722@gmail.com | N24: =VLOOKUP(B24,'DANH SACH UEH'!$A$3:$FE$2228,8,0) -> 0903017782 | O24: =IFERROR(VLOOKUP(AE24,'DS TAO MAIL'!$D$3:$M$1120,5,0),"") -> 31261570510 | P24: =IFERROR(VLOOKUP(AE24,'DS TAO MAIL'!$D$3:$M$1120,8,0),"") -> 84633605 | Q24: =IFERROR(VLOOKUP(AE24,'DS TAO MAIL'!$D$3:$M$1120,7,0),"") -> linhpham.31261570510@st.ueh.edu.vn | R24: =IFERROR(VLOOKUP(AE24,'DS TAO MAIL'!$D$3:$M$1120,8,0),"") -> 84633605 | S24: 80.81 | U24: 79.44 | V24: =IFERROR(IF(VLOOKUP(B24,'DANH SACH UEH'!$A$3:$FE$2228,27,0)="Không có","",IF(VLOOKUP(B24,'DANH SACH UEH'!$A$3:$FE$2228,29,0)<"6","",(VLOOKUP(B24,'DANH SACH UEH'!$A$3:$FE$2228,27,0)))),"") | W24: =IFERROR(IF(VLOOKUP(B24,'DANH SACH UEH'!$A$3:$FE$2228,29,0)<"6","",VLOOKUP(B24,'DANH SACH UEH'!$A$3:$FE$2228,29,0)),"") | X24: =IFERROR(IF(V24="","",VLOOKUP(B24,'DANH SACH UEH'!$A$3:$FE$2228,28,0)&""),"") | Z24: =VLOOKUP(B24,'DANH SACH UEH'!$A$3:$FE$2228,44,0) -> 7.06 | AA24: =VLOOKUP(B24,'DANH SACH UEH'!$A$3:$FE$2228,45,0) -> 7.54 | AB24: =VLOOKUP(B24,'DANH SACH UEH'!$A$3:$FE$2228,46,0) -> 7.70 | AE24: =VLOOKUP(B24,'DANH SACH UEH'!$A$3:$I$2229,4,0) -> PHẠM GIA LINH | AF24: =VLOOKUP(B24,'DANH SACH UEH'!$A$3:$I$2229,8,0) -> 0903017782
